Workbook

Sheet Assumptions
A1: AKBai Financial Model — Assumptions
A3: A — Exchange Rate
A4: USD to PHP Rate | B4: 57.2
A6: B — User Growth
A7: Beta users Month 1 | B7: 20
A8: Beta users Month 4 | B8: 80
A9: Free users Month 5 (launch) | B9: 90
A10: Pro users Month 5 (launch) | B10: 60
A11: Free % of total Y1 | B11: 0.6
A12: Free % of total Y2 | B12: 0.55
A13: Free % of total Y3 | B13: 0.55
A14: Pro % of total Y1 | B14: 0.4
A15: Pro % of total Y2 | B15: 0.38
A16: Pro % of total Y3 | B16: 0.38
A17: Business % of total Y1 | B17: 0
A18: Business % of total Y2 | B18: 0.07
... A26: Churn % Business (monthly) | B26: 0.03
A28: C — Pricing (₱/month)
A29: Beta price | B29: 149 | C29: Early access, limited features
A30: Pro price | B30: 299 | C30: Unlimited Sonnet + Haiku background
A31: Business price | B31: 799 | C31: Multi-seat + priority support
A32: Free price | B32: 0 | C32: 10 queries/day, Haiku only
A34: D — Claude API Costs
A35: Haiku input tokens/query Y1 | B35: 2000
A36: Haiku input tokens/query Y2 | B36: 2600 | C36: Growing context window
A37: Haiku input tokens/query Y3 | B37: 3200
A38: Haiku output tokens/query | B38: 500
A39: Haiku input cost per 1M tokens ($) | B39: 0.8
A40: Haiku output cost per 1M tokens ($) | B40: 4
A41: Free user avg queries/month | B41: 100 | C41: Cap: 10/day = 300/mo max; avg active = 100
A42: Sonnet input tokens/query Y1 | B42: 2000
A43: Sonnet input tokens/query Y2 | B43: 2600
A44: Sonnet input tokens/query Y3 | B44: 3200
A45: Sonnet output tokens/query | B45: 800
A46: Sonnet input cost per 1M tokens ($) | B46: 3
A47: Sonnet output cost per 1M tokens ($) | B47: 15
A48: Pro user avg queries/month | B48: 200
A49: Haiku background % of Pro queries | B49: 0.3 | C49: Background tasks use cheaper Haiku
A50: Prompt caching % of input tokens Y1 | B50: 0 | C50: Not yet implemented
A51: Prompt caching % of input tokens Y2 | B51: 0.4 | C51: 40% cached → 90% cheaper
...

Sheet User Growth
A1: Month | B1: Year | C1: Beta | D1: Free | E1: Pro | F1: Business | G1: Total | H1: New Free | I1: Churned | J1: Notes
A2: 1 | B2: Y1 | C2: 20 | D2: 0 | E2: 0 | F2: 0 | G2: =C2+D2+E2+F2 -> 20 | H2: =D2 -> 0 | I2: =ROUND(C2*Assumptions!$B$23+D2*Assumptions!$B$24+E2*Assumptions!$B$25+F2*Assumptions!$B$26,0) -> 1
A3: 2 | B3: Y1 | C3: 40 | D3: 0 | E3: 0 | F3: 0 | G3: =C3+D3+E3+F3 -> 40 | H3: =D3 -> 0 | I3: =ROUND(C3*Assumptions!$B$23+D3*Assumptions!$B$24+E3*Assumptions!$B$25+F3*Assumptions!$B$26,0) -> 1
A4: 3 | B4: Y1 | C4: 60 | D4: 0 | E4: 0 | F4: 0 | G4: =C4+D4+E4+F4 -> 60 | H4: =D4 -> 0 | I4: =ROUND(C4*Assumptions!$B$23+D4*Assumptions!$B$24+E4*Assumptions!$B$25+F4*Assumptions!$B$26,0) -> 2
A5: 4 | B5: Y1 | C5: 80 | D5: 0 | E5: 0 | F5: 0 | G5: =C5+D5+E5+F5 -> 80 | H5: =D5 -> 0 | I5: =ROUND(C5*Assumptions!$B$23+D5*Assumptions!$B$24+E5*Assumptions!$B$25+F5*Assumptions!$B$26,0) -> 2
A6: 5 | B6: Y1 | C6: 0 | D6: 90 | E6: 60 | F6: 0 | G6: =C6+D6+E6+F6 -> 150 | H6: =D6 -> 90 | I6: =ROUND(C6*Assumptions!$B$23+D6*Assumptions!$B$24+E6*Assumptions!$B$25+F6*Assumptions!$B$26,0) -> 10
A7: 6 | B7: Y1 | C7: 0 | D7: =ROUND(ROUND(G6*(1+Assumptions!$B$20),0)*Assumptions!$B$11,0) -> 104 | E7: =ROUND(ROUND(G6*(1+Assumptions!$B$20),0)*Assumptions!$B$14,0) -> 69 | F7: =ROUND(ROUND(G6*(1+Assumptions!$B$20),0)*Assumptions!$B$17,0) -> 0 | G7: =C7+D7+E7+F7 -> 173 | H7: =MAX(D7-D6,0) -> 14 | I7: =ROUND(C7*Assumptions!$B$23+D7*Assumptions!$B$24+E7*Assumptions!$B$25+F7*Assumptions!$B$26,0) -> 11
A8: 7 | B8: Y1 | C8: 0 | D8: =ROUND(ROUND(G7*(1+Assumptions!$B$20),0)*Assumptions!$B$11,0) -> 119 | E8: =ROUND(ROUND(G7*(1+Assumptions!$B$20),0)*Assumptions!$B$14,0) -> 80 | F8: =ROUND(ROUND(G7*(1+Assumptions!$B$20),0)*Assumptions!$B$17,0) -> 0 | G8: =C8+D8+E8+F8 -> 199 | H8: =MAX(D8-D7,0) -> 15 | I8: =ROUND(C8*Assumptions!$B$23+D8*Assumptions!$B$24+E8*Assumptions!$B$25+F8*Assumptions!$B$26,0) -> 13
A9: 8 | B9: Y1 | C9: 0 | D9: =ROUND(ROUND(G8*(1+Assumptions!$B$20),0)*Assumptions!$B$11,0) -> 137 | E9: =ROUND(ROUND(G8*(1+Assumptions!$B$20),0)*Assumptions!$B$14,0) -> 92 | F9: =ROUND(ROUND(G8*(1+Assumptions!$B$20),0)*Assumptions!$B$17,0) -> 0 | G9: =C9+D9+E9+F9 -> 229 | H9: =MAX(D9-D8,0) -> 18 | I9: =ROUND(C9*Assumptions!$B$23+D9*Assumptions!$B$24+E9*Assumptions!$B$25+F9*Assumptions!$B$26,0) -> 15
A10: 9 | B10: Y1 | C10: 0 | D10: =ROUND(ROUND(G9*(1+Assumptions!$B$20),0)*Assumptions!$B$11,0) -> 158 | E10: =ROUND(ROUND(G9*(1+Assumptions!$B$20),0)*Assumptions!$B$14,0) -> 105 | F10: =ROUND(ROUND(G9*(1+Assumptions!$B$20),0)*Assumptions!$B$17,0) -> 0 | G10: =C10+D10+E10+F10 -> 263 | H10: =MAX(D10-D9,0) -> 21 | I10: =ROUND(C10*Assumptions!$B$23+D10*Assumptions!$B$24+E10*Assumptions!$B$25+F10*Assumptions!$B$26,0) -> 17
A11: 10 | B11: Y1 | C11: 0 | D11: =ROUND(ROUND(G10*(1+Assumptions!$B$20),0)*Assumptions!$B$11,0) -> 181 | E11: =ROUND(ROUND(G10*(1+Assumptions!$B$20),0)*Assumptions!$B$14,0) -> 121 | F11: =ROUND(ROUND(G10*(1+Assumptions!$B$20),0)*Assumptions!$B$17,0) -> 0 | G11: =C11+D11+E11+F11 -> 302 | H11: =MAX(D11-D10,0) -> 23 | I11: =ROUND(C11*Assumptions!$B$23+D11*Assumptions!$B$24+E11*Assumptions!$B$25+F11*Assumptions!$B$26,0) -> 19
A12: 11 | B12: Y1 | C12: 0 | D12: =ROUND(ROUND(G11*(1+Assumptions!$B$20),0)*Assumptions!$B$11,0) -> 208 | E12: =ROUND(ROUND(G11*(1+Assumptions!$B$20),0)*Assumptions!$B$14,0) -> 139 | F12: =ROUND(ROUND(G11*(1+Assumptions!$B$20),0)*Assumptions!$B$17,0) -> 0 | G12: =C12+D12+E12+F12 -> 347 | H12: =MAX(D12-D11,0) -> 27 | I12: =ROUND(C12*Assumptions!$B$23+D12*Assumptions!$B$24+E12*Assumptions!$B$25+F12*Assumptions!$B$26,0) -> 22
A13: 12 | B13: Y1 | C13: 0 | D13: =ROUND(ROUND(G12*(1+Assumptions!$B$20),0)*Assumptions!$B$11,0) -> 239 | E13: =ROUND(ROUND(G12*(1+Assumptions!$B$20),0)*Assumptions!$B$14,0) -> 160 | F13: =ROUND(ROUND(G12*(1+Assumptions!$B$20),0)*Assumptions!$B$17,0) -> 0 | G13: =C13+D13+E13+F13 -> 399 | H13: =MAX(D13-D12,0) -> 31 | I13: =ROUND(C13*Assumptions!$B$23+D13*Assumptions!$B$24+E13*Assumptions!$B$25+F13*Assumptions!$B$26,0) -> 26
A14: 13 | B14: Y2 | C14: 0 | D14: =ROUND(ROUND(G13*(1+Assumptions!$B$21),0)*Assumptions!$B$12,0) -> 241 | E14: =ROUND(ROUND(G13*(1+Assumptions!$B$21),0)*Assumptions!$B$15,0) -> 167 | F14: =ROUND(ROUND(G13*(1+Assumptions!$B$21),0)*Assumptions!$B$18,0) -> 31 | G14: =C14+D14+E14+F14 -> 439 | H14: =MAX(D14-D13,0) -> 2 | I14: =ROUND(C14*Assumptions!$B$23+D14*Assumptions!$B$24+E14*Assumptions!$B$25+F14*Assumptions!$B$26,0) -> 27
A15: 14 | B15: Y2 | C15: 0 | D15: =ROUND(ROUND(G14*(1+Assumptions!$B$21),0)*Assumptions!$B$12,0) -> 266 | E15: =ROUND(ROUND(G14*(1+Assumptions!$B$21),0)*Assumptions!$B$15,0) -> 184 | F15: =ROUND(ROUND(G14*(1+Assumptions!$B$21),0)*Assumptions!$B$18,0) -> 34 | G15: =C15+D15+E15+F15 -> 484 | H15: =MAX(D15-D14,0) -> 25 | I15: =ROUND(C15*Assumptions!$B$23+D15*Assumptions!$B$24+E15*Assumptions!$B$25+F15*Assumptions!$B$26,0) -> 30
A16: 15 | B16: Y2 | C16: 0 | D16: =ROUND(ROUND(G15*(1+Assumptions!$B$21),0)*Assumptions!$B$12,0) -> 293 | E16: =ROUND(ROUND(G15*(1+Assumptions!$B$21),0)*Assumptions!$B$15,0) -> 202 | F16: =ROUND(ROUND(G15*(1+Assumptions!$B$21),0)*Assumptions!$B$18,0) -> 37 | G16: =C16+D16+E16+F16 -> 532 | H16: =MAX(D16-D15,0) -> 27 | I16: =ROUND(C16*Assumptions!$B$23+D16*Assumptions!$B$24+E16*Assumptions!$B$25+F16*Assumptions!$B$26,0) -> 33
A17: 16 | B17: Y2 | C17: 0 | D17: =ROUND(ROUND(G16*(1+Assumptions!$B$21),0)*Assumptions!$B$12,0) -> 322 | E17: =ROUND(ROUND(G16*(1+Assumptions!$B$21),0)*Assumptions!$B$15,0) -> 222 | F17: =ROUND(ROUND(G16*(1+Assumptions!$B$21),0)*Assumptions!$B$18,0) -> 41 | G17: =C17+D17+E17+F17 -> 585 | H17: =MAX(D17-D16,0) -> 29 | I17: =ROUND(C17*Assumptions!$B$23+D17*Assumptions!$B$24+E17*Assumptions!$B$25+F17*Assumptions!$B$26,0) -> 36
A18: 17 | B18: Y2 | C18: 0 | D18: =ROUND(ROUND(G17*(1+Assumptions!$B$21),0)*Assumptions!$B$12,0) -> 354 | E18: =ROUND(ROUND(G17*(1+Assumptions!$B$21),0)*Assumptions!$B$15,0) -> 245 | F18: =ROUND(ROUND(G17*(1+Assumptions!$B$21),0)*Assumptions!$B$18,0) -> 45 | G18: =C18+D18+E18+F18 -> 644 | H18: =MAX(D18-D17,0) -> 32 | I18: =ROUND(C18*Assumptions!$B$23+D18*Assumptions!$B$24+E18*Assumptions!$B$25+F18*Assumptions!$B$26,0) -> 39
A19: 18 | B19: Y2 | C19: 0 | D19: =ROUND(ROUND(G18*(1+Assumptions!$B$21),0)*Assumptions!$B$12,0) -> 389 | E19: =ROUND(ROUND(G18*(1+Assumptions!$B$21),0)*Assumptions!$B$15,0) -> 269 | F19: =ROUND(ROUND(G18*(1+Assumptions!$B$21),0)*Assumptions!$B$18,0) -> 50 | G19: =C19+D19+E19+F19 -> 708 | H19: =MAX(D19-D18,0) -> 35 | I19: =ROUND(C19*Assumptions!$B$23+D19*Assumptions!$B$24+E19*Assumptions!$B$25+F19*Assumptions!$B$26,0) -> 43
A20: 19 | B20: Y2 | C20: 0 | D20: =ROUND(ROUND(G19*(1+Assumptions!$B$21),0)*Assumptions!$B$12,0) -> 428 | E20: =ROUND(ROUND(G19*(1+Assumptions!$B$21),0)*Assumptions!$B$15,0) -> 296 | F20: =ROUND(ROUND(G19*(1+Assumptions!$B$21),0)*Assumptions!$B$18,0) -> 55 | G20: =C20+D20+E20+F20 -> 779 | H20: =MAX(D20-D19,0) -> 39 | I20: =ROUND(C20*Assumptions!$B$23+D20*Assumptions!$B$24+E20*Assumptions!$B$25+F20*Assumptions!$B$26,0) -> 48
A21: 20 | B21: Y2 | C21: 0 | D21: =ROUND(ROUND(G20*(1+Assumptions!$B$21),0)*Assumptions!$B$12,0) -> 471 | E21: =ROUND(ROUND(G20*(1+Assumptions!$B$21),0)*Assumptions!$B$15,0) -> 326 | F21: =ROUND(ROUND(G20*(1+Assumptions!$B$21),0)*Assumptions!$B$18,0) -> 60 | G21: =C21+D21+E21+F21 -> 857 | H21: =MAX(D21-D20,0) -> 43 | I21: =ROUND(C21*Assumptions!$B$23+D21*Assumptions!$B$24+E21*Assumptions!$B$25+F21*Assumptions!$B$26,0) -> 53
A22: 21 | B22: Y2 | C22: 0 | D22: =ROUND(ROUND(G21*(1+Assumptions!$B$21),0)*Assumptions!$B$12,0) -> 519 | E22: =ROUND(ROUND(G21*(1+Assumptions!$B$21),0)*Assumptions!$B$15,0) -> 358 | F22: =ROUND(ROUND(G21*(1+Assumptions!$B$21),0)*Assumptions!$B$18,0) -> 66 | G22: =C22+D22+E22+F22 -> 943 | H22: =MAX(D22-D21,0) -> 48 | I22: =ROUND(C22*Assumptions!$B$23+D22*Assumptions!$B$24+E22*Assumptions!$B$25+F22*Assumptions!$B$26,0) -> 58
A23: 22 | B23: Y2 | C23: 0 | D23: =ROUND(ROUND(G22*(1+Assumptions!$B$21),0)*Assumptions!$B$12,0) -> 570 | E23: =ROUND(ROUND(G22*(1+Assumptions!$B$21),0)*Assumptions!$B$15,0) -> 394 | F23: =ROUND(ROUND(G22*(1+Assumptions!$B$21),0)*Assumptions!$B$18,0) -> 73 | G23: =C23+D23+E23+F23 -> 1037 | H23: =MAX(D23-D22,0) -> 51 | I23: =ROUND(C23*Assumptions!$B$23+D23*Assumptions!$B$24+E23*Assumptions!$B$25+F23*Assumptions!$B$26,0) -> 64
A24: 23 | B24: Y2 | C24: 0 | D24: =ROUND(ROUND(G23*(1+Assumptions!$B$21),0)*Assumptions!$B$12,0) -> 628 | E24: =ROUND(ROUND(G23*(1+Assumptions!$B$21),0)*Assumptions!$B$15,0) -> 434 | F24: =ROUND(ROUND(G23*(1+Assumptions!$B$21),0)*Assumptions!$B$18,0) -> 80 | G24: =C24+D24+E24+F24 -> 1142 | H24: =MAX(D24-D23,0) -> 58 | I24: =ROUND(C24*Assumptions!$B$23+D24*Assumptions!$B$24+E24*Assumptions!$B$25+F24*Assumptions!$B$26,0) -> 70
A25: 24 | B25: Y2 | C25: 0 | D25: =ROUND(ROUND(G24*(1+Assumptions!$B$21),0)*Assumptions!$B$12,0) -> 691 | E25: =ROUND(ROUND(G24*(1+Assumptions!$B$21),0)*Assumptions!$B$15,0) -> 477 | F25: =ROUND(ROUND(G24*(1+Assumptions!$B$21),0)*Assumptions!$B$18,0) -> 88 | G25: =C25+D25+E25+F25 -> 1256 | H25: =MAX(D25-D24,0) -> 63 | I25: =ROUND(C25*Assumptions!$B$23+D25*Assumptions!$B$24+E25*Assumptions!$B$25+F25*Assumptions!$B$26,0) -> 77
A26: 25 | B26: Y3 | C26: 0 | D26: =ROUND(ROUND(G25*(1+Assumptions!$B$22),0)*Assumptions!$B$13,0) -> 746 | E26: =ROUND(ROUND(G25*(1+Assumptions!$B$22),0)*Assumptions!$B$16,0) -> 515 | F26: =ROUND(ROUND(G25*(1+Assumptions!$B$22),0)*Assumptions!$B$19,0) -> 95 | G26: =C26+D26+E26+F26 -> 1356 | H26: =MAX(D26-D25,0) -> 55 | I26: =ROUND(C26*Assumptions!$B$23+D26*Assumptions!$B$24+E26*Assumptions!$B$25+F26*Assumptions!$B$26,0) -> 83
A27: 26 | B27: Y3 | C27: 0 | D27: =ROUND(ROUND(G26*(1+Assumptions!$B$22),0)*Assumptions!$B$13,0) -> 805 | E27: =ROUND(ROUND(G26*(1+Assumptions!$B$22),0)*Assumptions!$B$16,0) -> 556 | F27: =ROUND(ROUND(G26*(1+Assumptions!$B$22),0)*Assumptions!$B$19,0) -> 102 | G27: =C27+D27+E27+F27 -> 1463 | H27: =MAX(D27-D26,0) -> 59 | I27: =ROUND(C27*Assumptions!$B$23+D27*Assumptions!$B$24+E27*Assumptions!$B$25+F27*Assumptions!$B$26,0) -> 90
A28: 27 | B28: Y3 | C28: 0 | D28: =ROUND(ROUND(G27*(1+Assumptions!$B$22),0)*Assumptions!$B$13,0) -> 869 | E28: =ROUND(ROUND(G27*(1+Assumptions!$B$22),0)*Assumptions!$B$16,0) -> 600 | F28: =ROUND(ROUND(G27*(1+Assumptions!$B$22),0)*Assumptions!$B$19,0) -> 111 | G28: =C28+D28+E28+F28 -> 1580 | H28: =MAX(D28-D27,0) -> 64 | I28: =ROUND(C28*Assumptions!$B$23+D28*Assumptions!$B$24+E28*Assumptions!$B$25+F28*Assumptions!$B$26,0) -> 97
A29: 28 | B29: Y3 | C29: 0 | D29: =ROUND(ROUND(G28*(1+Assumptions!$B$22),0)*Assumptions!$B$13,0) -> 938 | E29: =ROUND(ROUND(G28*(1+Assumptions!$B$22),0)*Assumptions!$B$16,0) -> 648 | F29: =ROUND(ROUND(G28*(1+Assumptions!$B$22),0)*Assumptions!$B$19,0) -> 119 | G29: =C29+D29+E29+F29 -> 1705 | H29: =MAX(D29-D28,0) -> 69 | I29: =ROUND(C29*Assumptions!$B$23+D29*Assumptions!$B$24+E29*Assumptions!$B$25+F29*Assumptions!$B$26,0) -> 105
A30: 29 | B30: Y3 | C30: 0 | D30: =ROUND(ROUND(G29*(1+Assumptions!$B$22),0)*Assumptions!$B$13,0) -> 1013 | E30: =ROUND(ROUND(G29*(1+Assumptions!$B$22),0)*Assumptions!$B$16,0) -> 700 | F30: =ROUND(ROUND(G29*(1+Assumptions!$B$22),0)*Assumptions!$B$19,0) -> 129 | G30: =C30+D30+E30+F30 -> 1842 | H30: =MAX(D30-D29,0) -> 75 | I30: =ROUND(C30*Assumptions!$B$23+D30*Assumptions!$B$24+E30*Assumptions!$B$25+F30*Assumptions!$B$26,0) -> 113
A31: 30 | B31: Y3 | C31: 0 | D31: =ROUND(ROUND(G30*(1+Assumptions!$B$22),0)*Assumptions!$B$13,0) -> 1094 | E31: =ROUND(ROUND(G30*(1+Assumptions!$B$22),0)*Assumptions!$B$16,0) -> 756 | F31: =ROUND(ROUND(G30*(1+Assumptions!$B$22),0)*Assumptions!$B$19,0) -> 139 | G31: =C31+D31+E31+F31 -> 1989 | H31: =MAX(D31-D30,0) -> 81 | I31: =ROUND(C31*Assumptions!$B$23+D31*Assumptions!$B$24+E31*Assumptions!$B$25+F31*Assumptions!$B$26,0) -> 122
A32: 31 | B32: Y3 | C32: 0 | D32: =ROUND(ROUND(G31*(1+Assumptions!$B$22),0)*Assumptions!$B$13,0) -> 1181 | E32: =ROUND(ROUND(G31*(1+Assumptions!$B$22),0)*Assumptions!$B$16,0) -> 816 | F32: =ROUND(ROUND(G31*(1+Assumptions!$B$22),0)*Assumptions!$B$19,0) -> 150 | G32: =C32+D32+E32+F32 -> 2147 | H32: =MAX(D32-D31,0) -> 87 | I32: =ROUND(C32*Assumptions!$B$23+D32*Assumptions!$B$24+E32*Assumptions!$B$25+F32*Assumptions!$B$26,0) -> 132
A33: 32 | B33: Y3 | C33: 0 | D33: =ROUND(ROUND(G32*(1+Assumptions!$B$22),0)*Assumptions!$B$13,0) -> 1275 | E33: =ROUND(ROUND(G32*(1+Assumptions!$B$22),0)*Assumptions!$B$16,0) -> 881 | F33: =ROUND(ROUND(G32*(1+Assumptions!$B$22),0)*Assumptions!$B$19,0) -> 162 | G33: =C33+D33+E33+F33 -> 2318 | H33: =MAX(D33-D32,0) -> 94 | I33: =ROUND(C33*Assumptions!$B$23+D33*Assumptions!$B$24+E33*Assumptions!$B$25+F33*Assumptions!$B$26,0) -> 142
A34: 33 | B34: Y3 | C34: 0 | D34: =ROUND(ROUND(G33*(1+Assumptions!$B$22),0)*Assumptions!$B$13,0) -> 1377 | E34: =ROUND(ROUND(G33*(1+Assumptions!$B$22),0)*Assumptions!$B$16,0) -> 951 | F34: =ROUND(ROUND(G33*(1+Assumptions!$B$22),0)*Assumptions!$B$19,0) -> 175 | G34: =C34+D34+E34+F34 -> 2503 | H34: =MAX(D34-D33,0) -> 102 | I34: =ROUND(C34*Assumptions!$B$23+D34*Assumptions!$B$24+E34*Assumptions!$B$25+F34*Assumptions!$B$26,0) -> 153
A35: 34 | B35: Y3 | C35: 0 | D35: =ROUND(ROUND(G34*(1+Assumptions!$B$22),0)*Assumptions!$B$13,0) -> 1487 | E35: =ROUND(ROUND(G34*(1+Assumptions!$B$22),0)*Assumptions!$B$16,0) -> 1027 | F35: =ROUND(ROUND(G34*(1+Assumptions!$B$22),0)*Assumptions!$B$19,0) -> 189 | G35: =C35+D35+E35+F35 -> 2703 | H35: =MAX(D35-D34,0) -> 110 | I35: =ROUND(C35*Assumptions!$B$23+D35*Assumptions!$B$24+E35*Assumptions!$B$25+F35*Assumptions!$B$26,0) -> 166
A36: 35 | B36: Y3 | C36: 0 | D36: =ROUND(ROUND(G35*(1+Assumptions!$B$22),0)*Assumptions!$B$13,0) -> 1605 | E36: =ROUND(ROUND(G35*(1+Assumptions!$B$22),0)*Assumptions!$B$16,0) -> 1109 | F36: =ROUND(ROUND(G35*(1+Assumptions!$B$22),0)*Assumptions!$B$19,0) -> 204 | G36: =C36+D36+E36+F36 -> 2918 | H36: =MAX(D36-D35,0) -> 118 | I36: =ROUND(C36*Assumptions!$B$23+D36*Assumptions!$B$24+E36*Assumptions!$B$25+F36*Assumptions!$B$26,0) -> 179
A37: 36 | B37: Y3 | C37: 0 | D37: =ROUND(ROUND(G36*(1+Assumptions!$B$22),0)*Assumptions!$B$13,0) -> 1733 | E37: =ROUND(ROUND(G36*(1+Assumptions!$B$22),0)*Assumptions!$B$16,0) -> 1197 | F37: =ROUND(ROUND(G36*(1+Assumptions!$B$22),0)*Assumptions!$B$19,0) -> 221 | G37: =C37+D37+E37+F37 -> 3151 | H37: =MAX(D37-D36,0) -> 128 | I37: =ROUND(C37*Assumptions!$B$23+D37*Assumptions!$B$24+E37*Assumptions!$B$25+F37*Assumptions!$B$26,0) -> 193

Sheet Revenue
A1: Month | B1: Year | C1: Beta Rev | D1: Pro Rev | E1: Biz Rev | F1: Gross Rev | G1: Xendit Fee | H1: Net Rev | I1: Cumul Net Rev
A2: 1 | B2: Y1 | C2: ='User Growth'!C2*Assumptions!$B$29 -> 2980 | D2: ='User Growth'!E2*Assumptions!$B$30 -> 0 | E2: ='User Growth'!F2*Assumptions!$B$31 -> 0 | F2: =C2+D2+E2 -> 2980 | G2: =F2*Assumptions!$B$65 -> 56.62 | H2: =F2-G2 -> 2923.38 | I2: =H2 -> 2923.38
A3: 2 | B3: Y1 | C3: ='User Growth'!C3*Assumptions!$B$29 -> 5960 | D3: ='User Growth'!E3*Assumptions!$B$30 -> 0 | E3: ='User Growth'!F3*Assumptions!$B$31 -> 0 | F3: =C3+D3+E3 -> 5960 | G3: =F3*Assumptions!$B$65 -> 113.24 | H3: =F3-G3 -> 5846.76 | I3: =I2+H3 -> 8770.14
A4: 3 | B4: Y1 | C4: ='User Growth'!C4*Assumptions!$B$29 -> 8940 | D4: ='User Growth'!E4*Assumptions!$B$30 -> 0 | E4: ='User Growth'!F4*Assumptions!$B$31 -> 0 | F4: =C4+D4+E4 -> 8940 | G4: =F4*Assumptions!$B$65 -> 169.86 | H4: =F4-G4 -> 8770.14 | I4: =I3+H4 -> 17540.28
A5: 4 | B5: Y1 | C5: ='User Growth'!C5*Assumptions!$B$29 -> 11920 | D5: ='User Growth'!E5*Assumptions!$B$30 -> 0 | E5: ='User Growth'!F5*Assumptions!$B$31 -> 0 | F5: =C5+D5+E5 -> 11920 | G5: =F5*Assumptions!$B$65 -> 226.48 | H5: =F5-G5 -> 11693.52 | I5: =I4+H5 -> 29233.8
A6: 5 | B6: Y1 | C6: ='User Growth'!C6*Assumptions!$B$29 -> 0 | D6: ='User Growth'!E6*Assumptions!$B$30 -> 17940 | E6: ='User Growth'!F6*Assumptions!$B$31 -> 0 | F6: =C6+D6+E6 -> 17940 | G6: =F6*Assumptions!$B$65 -> 340.86 | H6: =F6-G6 -> 17599.14 | I6: =I5+H6 -> 46832.94
A7: 6 | B7: Y1 | C7: ='User Growth'!C7*Assumptions!$B$29 -> 0 | D7: ='User Growth'!E7*Assumptions!$B$30 -> 20631 | E7: ='User Growth'!F7*Assumptions!$B$31 -> 0 | F7: =C7+D7+E7 -> 20631 | G7: =F7*Assumptions!$B$65 -> 391.989 | H7: =F7-G7 -> 20239.011 | I7: =I6+H7 -> 67071.951
A8: 7 | B8: Y1 | C8: ='User Growth'!C8*Assumptions!$B$29 -> 0 | D8: ='User Growth'!E8*Assumptions!$B$30 -> 23920 | E8: ='User Growth'!F8*Assumptions!$B$31 -> 0 | F8: =C8+D8+E8 -> 23920 | G8: =F8*Assumptions!$B$65 -> 454.48 | H8: =F8-G8 -> 23465.52 | I8: =I7+H8 -> 90537.471
A9: 8 | B9: Y1 | C9: ='User Growth'!C9*Assumptions!$B$29 -> 0 | D9: ='User Growth'!E9*Assumptions!$B$30 -> 27508 | E9: ='User Growth'!F9*Assumptions!$B$31 -> 0 | F9: =C9+D9+E9 -> 27508 | G9: =F9*Assumptions!$B$65 -> 522.652 | H9: =F9-G9 -> 26985.348 | I9: =I8+H9 -> 117522.82
A10: 9 | B10: Y1 | C10: ='User Growth'!C10*Assumptions!$B$29 -> 0 | D10: ='User Growth'!E10*Assumptions!$B$30 -> 31395 | E10: ='User Growth'!F10*Assumptions!$B$31 -> 0 | F10: =C10+D10+E10 -> 31395 | G10: =F10*Assumptions!$B$65 -> 596.505 | H10: =F10-G10 -> 30798.495 | I10: =I9+H10 -> 148321.31
A11: 10 | B11: Y1 | C11: ='User Growth'!C11*Assumptions!$B$29 -> 0 | D11: ='User Growth'!E11*Assumptions!$B$30 -> 36179 | E11: ='User Growth'!F11*Assumptions!$B$31 -> 0 | F11: =C11+D11+E11 -> 36179 | G11: =F11*Assumptions!$B$65 -> 687.401 | H11: =F11-G11 -> 35491.599 | I11: =I10+H11 -> 183812.91
A12: 11 | B12: Y1 | C12: ='User Growth'!C12*Assumptions!$B$29 -> 0 | D12: ='User Growth'!E12*Assumptions!$B$30 -> 41561 | E12: ='User Growth'!F12*Assumptions!$B$31 -> 0 | F12: =C12+D12+E12 -> 41561 | G12: =F12*Assumptions!$B$65 -> 789.659 | H12: =F12-G12 -> 40771.341 | I12: =I11+H12 -> 224584.25
A13: 12 | B13: Y1 | C13: ='User Growth'!C13*Assumptions!$B$29 -> 0 | D13: ='User Growth'!E13*Assumptions!$B$30 -> 47840 | E13: ='User Growth'!F13*Assumptions!$B$31 -> 0 | F13: =C13+D13+E13 -> 47840 | G13: =F13*Assumptions!$B$65 -> 908.96 | H13: =F13-G13 -> 46931.04 | I13: =I12+H13 -> 271515.29
A14: 13 | B14: Y2 | C14: ='User Growth'!C14*Assumptions!$B$29 -> 0 | D14: ='User Growth'!E14*Assumptions!$B$30 -> 49933 | E14: ='User Growth'!F14*Assumptions!$B$31 -> 24769 | F14: =C14+D14+E14 -> 74702 | G14: =F14*Assumptions!$B$65 -> 1419.338 | H14: =F14-G14 -> 73282.662 | I14: =I13+H14 -> 344797.96
... A37: 36 | B37: Y3 | C37: ='User Growth'!C37*Assumptions!$B$29 -> 0 | D37: ='User Growth'!E37*Assumptions!$B$30 -> 357903 | E37: ='User Growth'!F37*Assumptions!$B$31 -> 176579 | F37: =C37+D37+E37 -> 534482 | G37: =F37*Assumptions!$B$65 -> 10155.158 | H37: =F37-G37 -> 524326.84 | I37: =I36+H37 -> 6106517

Sheet API Costs
A1: Month | B1: Year | C1: Free Users | D1: Pro Users | E1: Biz Users | F1: Yr Mult | G1: Cache% | H1: Free Cost/User | I1: Pro Cost/User | J1: Biz Cost/User | K1: Total Free API | L1: Total Pro API | M1: Total Biz API | N1: TOTAL API COST
A2: 1 | B2: Y1 | C2: ='User Growth'!D2 -> 0 | D2: ='User Growth'!E2 -> 0 | E2: ='User Growth'!F2 -> 0 | F2: =IF(B2="Y1",Assumptions!$B$53,IF(B2="Y2",Assumptions!$B$54,Assumptions!$B$55)) -> 1 | G2: =IF(B2="Y1",Assumptions!$B$50,IF(B2="Y2",Assumptions!$B$51,Assumptions!$B$52)) -> 0 | H2: =((IF(B2="Y1",Assumptions!$B$35,IF(B2="Y2",Assumptions!$B$36,Assumptions!$B$37)))/1000000*Assumptions!$B$39+Assumptions!$B$38/1000000*Assumptions!$B$40)*F2*Assumptions!$B$41*Assumptions!$B$4 -> 20.592 | I2: =((IF(B2="Y1",Assumptions!$B$42,IF(B2="Y2",Assumptions!$B$43,Assumptions!$B$44))*(1-G2*0.9)/1000000*Assumptions!$B$46+Assumptions!$B$45/1000000*Assumptions!$B$47)*Assumptions!$B$48*(1-Assumptions!$B$49)+((IF(B2="Y1",Assumptions!$B$35,IF(B2="Y2",Assumptions!$B$36,Assumptions!$B$37)))/1000000*Assumptions!$B$39+Assumptions!$B$38/1000000*Assumptions!$B$40)*Assumptions!$B$48*Assumptions!$B$49+Assumptions!$B$56*Assumptions!$B$57)*F2*Assumptions!$B$4 -> 158.9016 | J2: =((IF(B2="Y1",Assumptions!$B$42,IF(B2="Y2",Assumptions!$B$43,Assumptions!$B$44))*(1-G2*0.9)/1000000*Assumptions!$B$46+Assumptions!$B$45/1000000*Assumptions!$B$47)*Assumptions!$B$48*(1-Assumptions!$B$49)+((IF(B2="Y1",Assumptions!$B$35,IF(B2="Y2",Assumptions!$B$36,Assumptions!$B$37)))/1000000*Assumptions!$B$39+Assumptions!$B$38/1000000*Assumptions!$B$40)*Assumptions!$B$48*Assumptions!$B$49+Assumptions!$B$56*Assumptions!$B$58)*F2*Assumptions!$B$4 -> 161.304 | K2: =C2*H2 -> 0 | L2: =D2*I2 -> 0 | M2: =E2*J2 -> 0 | N2: =K2+L2+M2 -> 0
A3: 2 | B3: Y1 | C3: ='User Growth'!D3 -> 0 | D3: ='User Growth'!E3 -> 0 | E3: ='User Growth'!F3 -> 0 | F3: =IF(B3="Y1",Assumptions!$B$53,IF(B3="Y2",Assumptions!$B$54,Assumptions!$B$55)) -> 1 | G3: =IF(B3="Y1",Assumptions!$B$50,IF(B3="Y2",Assumptions!$B$51,Assumptions!$B$52)) -> 0 | H3: =((IF(B3="Y1",Assumptions!$B$35,IF(B3="Y2",Assumptions!$B$36,Assumptions!$B$37)))/1000000*Assumptions!$B$39+Assumptions!$B$38/1000000*Assumptions!$B$40)*F3*Assumptions!$B$41*Assumptions!$B$4 -> 20.592 | I3: =((IF(B3="Y1",Assumptions!$B$42,IF(B3="Y2",Assumptions!$B$43,Assumptions!$B$44))*(1-G3*0.9)/1000000*Assumptions!$B$46+Assumptions!$B$45/1000000*Assumptions!$B$47)*Assumptions!$B$48*(1-Assumptions!$B$49)+((IF(B3="Y1",Assumptions!$B$35,IF(B3="Y2",Assumptions!$B$36,Assumptions!$B$37)))/1000000*Assumptions!$B$39+Assumptions!$B$38/1000000*Assumptions!$B$40)*Assumptions!$B$48*Assumptions!$B$49+Assumptions!$B$56*Assumptions!$B$57)*F3*Assumptions!$B$4 -> 158.9016 | J3: =((IF(B3="Y1",Assumptions!$B$42,IF(B3="Y2",Assumptions!$B$43,Assumptions!$B$44))*(1-G3*0.9)/1000000*Assumptions!$B$46+Assumptions!$B$45/1000000*Assumptions!$B$47)*Assumptions!$B$48*(1-Assumptions!$B$49)+((IF(B3="Y1",Assumptions!$B$35,IF(B3="Y2",Assumptions!$B$36,Assumptions!$B$37)))/1000000*Assumptions!$B$39+Assumptions!$B$38/1000000*Assumptions!$B$40)*Assumptions!$B$48*Assumptions!$B$49+Assumptions!$B$56*Assumptions!$B$58)*F3*Assumptions!$B$4 -> 161.304 | K3: =C3*H3 -> 0 | L3: =D3*I3 -> 0 | M3: =E3*J3 -> 0 | N3: =K3+L3+M3 -> 0
A4: 3 | B4: Y1 | C4: ='User Growth'!D4 -> 0 | D4: ='User Growth'!E4 -> 0 | E4: ='User Growth'!F4 -> 0 | F4: =IF(B4="Y1",Assumptions!$B$53,IF(B4="Y2",Assumptions!$B$54,Assumptions!$B$55)) -> 1 | G4: =IF(B4="Y1",Assumptions!$B$50,IF(B4="Y2",Assumptions!$B$51,Assumptions!$B$52)) -> 0 | H4: =((IF(B4="Y1",Assumptions!$B$35,IF(B4="Y2",Assumptions!$B$36,Assumptions!$B$37)))/1000000*Assumptions!$B$39+Assumptions!$B$38/1000000*Assumptions!$B$40)*F4*Assumptions!$B$41*Assumptions!$B$4 -> 20.592 | I4: =((IF(B4="Y1",Assumptions!$B$42,IF(B4="Y2",Assumptions!$B$43,Assumptions!$B$44))*(1-G4*0.9)/1000000*Assumptions!$B$46+Assumptions!$B$45/1000000*Assumptions!$B$47)*Assumptions!$B$48*(1-Assumptions!$B$49)+((IF(B4="Y1",Assumptions!$B$35,IF(B4="Y2",Assumptions!$B$36,Assumptions!$B$37)))/1000000*Assumptions!$B$39+Assumptions!$B$38/1000000*Assumptions!$B$40)*Assumptions!$B$48*Assumptions!$B$49+Assumptions!$B$56*Assumptions!$B$57)*F4*Assumptions!$B$4 -> 158.9016 | J4: =((IF(B4="Y1",Assumptions!$B$42,IF(B4="Y2",Assumptions!$B$43,Assumptions!$B$44))*(1-G4*0.9)/1000000*Assumptions!$B$46+Assumptions!$B$45/1000000*Assumptions!$B$47)*Assumptions!$B$48*(1-Assumptions!$B$49)+((IF(B4="Y1",Assumptions!$B$35,IF(B4="Y2",Assumptions!$B$36,Assumptions!$B$37)))/1000000*Assumptions!$B$39+Assumptions!$B$38/1000000*Assumptions!$B$40)*Assumptions!$B$48*Assumptions!$B$49+Assumptions!$B$56*Assumptions!$B$58)*F4*Assumptions!$B$4 -> 161.304 | K4: =C4*H4 -> 0 | L4: =D4*I4 -> 0 | M4: =E4*J4 -> 0 | N4: =K4+L4+M4 -> 0
A5: 4 | B5: Y1 | C5: ='User Growth'!D5 -> 0 | D5: ='User Growth'!E5 -> 0 | E5: ='User Growth'!F5 -> 0 | F5: =IF(B5="Y1",Assumptions!$B$53,IF(B5="Y2",Assumptions!$B$54,Assumptions!$B$55)) -> 1 | G5: =IF(B5="Y1",Assumptions!$B$50,IF(B5="Y2",Assumptions!$B$51,Assumptions!$B$52)) -> 0 | H5: =((IF(B5="Y1",Assumptions!$B$35,IF(B5="Y2",Assumptions!$B$36,Assumptions!$B$37)))/1000000*Assumptions!$B$39+Assumptions!$B$38/1000000*Assumptions!$B$40)*F5*Assumptions!$B$41*Assumptions!$B$4 -> 20.592 | I5: =((IF(B5="Y1",Assumptions!$B$42,IF(B5="Y2",Assumptions!$B$43,Assumptions!$B$44))*(1-G5*0.9)/1000000*Assumptions!$B$46+Assumptions!$B$45/1000000*Assumptions!$B$47)*Assumptions!$B$48*(1-Assumptions!$B$49)+((IF(B5="Y1",Assumptions!$B$35,IF(B5="Y2",Assumptions!$B$36,Assumptions!$B$37)))/1000000*Assumptions!$B$39+Assumptions!$B$38/1000000*Assumptions!$B$40)*Assumptions!$B$48*Assumptions!$B$49+Assumptions!$B$56*Assumptions!$B$57)*F5*Assumptions!$B$4 -> 158.9016 | J5: =((IF(B5="Y1",Assumptions!$B$42,IF(B5="Y2",Assumptions!$B$43,Assumptions!$B$44))*(1-G5*0.9)/1000000*Assumptions!$B$46+Assumptions!$B$45/1000000*Assumptions!$B$47)*Assumptions!$B$48*(1-Assumptions!$B$49)+((IF(B5="Y1",Assumptions!$B$35,IF(B5="Y2",Assumptions!$B$36,Assumptions!$B$37)))/1000000*Assumptions!$B$39+Assumptions!$B$38/1000000*Assumptions!$B$40)*Assumptions!$B$48*Assumptions!$B$49+Assumptions!$B$56*Assumptions!$B$58)*F5*Assumptions!$B$4 -> 161.304 | K5: =C5*H5 -> 0 | L5: =D5*I5 -> 0 | M5: =E5*J5 -> 0 | N5: =K5+L5+M5 -> 0
A6: 5 | B6: Y1 | C6: ='User Growth'!D6 -> 90 | D6: ='User Growth'!E6 -> 60 | E6: ='User Growth'!F6 -> 0 | F6: =IF(B6="Y1",Assumptions!$B$53,IF(B6="Y2",Assumptions!$B$54,Assumptions!$B$55)) -> 1 | G6: =IF(B6="Y1",Assumptions!$B$50,IF(B6="Y2",Assumptions!$B$51,Assumptions!$B$52)) -> 0 | H6: =((IF(B6="Y1",Assumptions!$B$35,IF(B6="Y2",Assumptions!$B$36,Assumptions!$B$37)))/1000000*Assumptions!$B$39+Assumptions!$B$38/1000000*Assumptions!$B$40)*F6*Assumptions!$B$41*Assumptions!$B$4 -> 20.592 | I6: =((IF(B6="Y1",Assumptions!$B$42,IF(B6="Y2",Assumptions!$B$43,Assumptions!$B$44))*(1-G6*0.9)/1000000*Assumptions!$B$46+Assumptions!$B$45/1000000*Assumptions!$B$47)*Assumptions!$B$48*(1-Assumptions!$B$49)+((IF(B6="Y1",Assumptions!$B$35,IF(B6="Y2",Assumptions!$B$36,Assumptions!$B$37)))/1000000*Assumptions!$B$39+Assumptions!$B$38/1000000*Assumptions!$B$40)*Assumptions!$B$48*Assumptions!$B$49+Assumptions!$B$56*Assumptions!$B$57)*F6*Assumptions!$B$4 -> 158.9016 | J6: =((IF(B6="Y1",Assumptions!$B$42,IF(B6="Y2",Assumptions!$B$43,Assumptions!$B$44))*(1-G6*0.9)/1000000*Assumptions!$B$46+Assumptions!$B$45/1000000*Assumptions!$B$47)*Assumptions!$B$48*(1-Assumptions!$B$49)+((IF(B6="Y1",Assumptions!$B$35,IF(B6="Y2",Assumptions!$B$36,Assumptions!$B$37)))/1000000*Assumptions!$B$39+Assumptions!$B$38/1000000*Assumptions!$B$40)*Assumptions!$B$48*Assumptions!$B$49+Assumptions!$B$56*Assumptions!$B$58)*F6*Assumptions!$B$4 -> 161.304 | K6: =C6*H6 -> 1853.28 | L6: =D6*I6 -> 9534.096 | M6: =E6*J6 -> 0 | N6: =K6+L6+M6 -> 11387.376
A7: 6 | B7: Y1 | C7: ='User Growth'!D7 -> 104 | D7: ='User Growth'!E7 -> 69 | E7: ='User Growth'!F7 -> 0 | F7: =IF(B7="Y1",Assumptions!$B$53,IF(B7="Y2",Assumptions!$B$54,Assumptions!$B$55)) -> 1 | G7: =IF(B7="Y1",Assumptions!$B$50,IF(B7="Y2",Assumptions!$B$51,Assumptions!$B$52)) -> 0 | H7: =((IF(B7="Y1",Assumptions!$B$35,IF(B7="Y2",Assumptions!$B$36,Assumptions!$B$37)))/1000000*Assumptions!$B$39+Assumptions!$B$38/1000000*Assumptions!$B$40)*F7*Assumptions!$B$41*Assumptions!$B$4 -> 20.592 | I7: =((IF(B7="Y1",Assumptions!$B$42,IF(B7="Y2",Assumptions!$B$43,Assumptions!$B$44))*(1-G7*0.9)/1000000*Assumptions!$B$46+Assumptions!$B$45/1000000*Assumptions!$B$47)*Assumptions!$B$48*(1-Assumptions!$B$49)+((IF(B7="Y1",Assumptions!$B$35,IF(B7="Y2",Assumptions!$B$36,Assumptions!$B$37)))/1000000*Assumptions!$B$39+Assumptions!$B$38/1000000*Assumptions!$B$40)*Assumptions!$B$48*Assumptions!$B$49+Assumptions!$B$56*Assumptions!$B$57)*F7*Assumptions!$B$4 -> 158.9016 | J7: =((IF(B7="Y1",Assumptions!$B$42,IF(B7="Y2",Assumptions!$B$43,Assumptions!$B$44))*(1-G7*0.9)/1000000*Assumptions!$B$46+Assumptions!$B$45/1000000*Assumptions!$B$47)*Assumptions!$B$48*(1-Assumptions!$B$49)+((IF(B7="Y1",Assumptions!$B$35,IF(B7="Y2",Assumptions!$B$36,Assumptions!$B$37)))/1000000*Assumptions!$B$39+Assumptions!$B$38/1000000*Assumptions!$B$40)*Assumptions!$B$48*Assumptions!$B$49+Assumptions!$B$56*Assumptions!$B$58)*F7*Assumptions!$B$4 -> 161.304 | K7: =C7*H7 -> 2141.568 | L7: =D7*I7 -> 10964.21 | M7: =E7*J7 -> 0 | N7: =K7+L7+M7 -> 13105.778
A8: 7 | B8: Y1 | C8: ='User Growth'!D8 -> 119 | D8: ='User Growth'!E8 -> 80 | E8: ='User Growth'!F8 -> 0 | F8: =IF(B8="Y1",Assumptions!$B$53,IF(B8="Y2",Assumptions!$B$54,Assumptions!$B$55)) -> 1 | G8: =IF(B8="Y1",Assumptions!$B$50,IF(B8="Y2",Assumptions!$B$51,Assumptions!$B$52)) -> 0 | H8: =((IF(B8="Y1",Assumptions!$B$35,IF(B8="Y2",Assumptions!$B$36,Assumptions!$B$37)))/1000000*Assumptions!$B$39+Assumptions!$B$38/1000000*Assumptions!$B$40)*F8*Assumptions!$B$41*Assumptions!$B$4 -> 20.592 | I8: =((IF(B8="Y1",Assumptions!$B$42,IF(B8="Y2",Assumptions!$B$43,Assumptions!$B$44))*(1-G8*0.9)/1000000*Assumptions!$B$46+Assumptions!$B$45/1000000*Assumptions!$B$47)*Assumptions!$B$48*(1-Assumptions!$B$49)+((IF(B8="Y1",Assumptions!$B$35,IF(B8="Y2",Assumptions!$B$36,Assumptions!$B$37)))/1000000*Assumptions!$B$39+Assumptions!$B$38/1000000*Assumptions!$B$40)*Assumptions!$B$48*Assumptions!$B$49+Assumptions!$B$56*Assumptions!$B$57)*F8*Assumptions!$B$4 -> 158.9016 | J8: =((IF(B8="Y1",Assumptions!$B$42,IF(B8="Y2",Assumptions!$B$43,Assumptions!$B$44))*(1-G8*0.9)/1000000*Assumptions!$B$46+Assumptions!$B$45/1000000*Assumptions!$B$47)*Assumptions!$B$48*(1-Assumptions!$B$49)+((IF(B8="Y1",Assumptions!$B$35,IF(B8="Y2",Assumptions!$B$36,Assumptions!$B$37)))/1000000*Assumptions!$B$39+Assumptions!$B$38/1000000*Assumptions!$B$40)*Assumptions!$B$48*Assumptions!$B$49+Assumptions!$B$56*Assumptions!$B$58)*F8*Assumptions!$B$4 -> 161.304 | K8: =C8*H8 -> 2450.448 | L8: =D8*I8 -> 12712.128 | M8: =E8*J8 -> 0 | N8: =K8+L8+M8 -> 15162.576
A9: 8 | B9: Y1 | C9: ='User Growth'!D9 -> 137 | D9: ='User Growth'!E9 -> 92 | E9: ='User Growth'!F9 -> 0 | F9: =IF(B9="Y1",Assumptions!$B$53,IF(B9="Y2",Assumptions!$B$54,Assumptions!$B$55)) -> 1 | G9: =IF(B9="Y1",Assumptions!$B$50,IF(B9="Y2",Assumptions!$B$51,Assumptions!$B$52)) -> 0 | H9: =((IF(B9="Y1",Assumptions!$B$35,IF(B9="Y2",Assumptions!$B$36,Assumptions!$B$37)))/1000000*Assumptions!$B$39+Assumptions!$B$38/1000000*Assumptions!$B$40)*F9*Assumptions!$B$41*Assumptions!$B$4 -> 20.592 | I9: =((IF(B9="Y1",Assumptions!$B$42,IF(B9="Y2",Assumptions!$B$43,Assumptions!$B$44))*(1-G9*0.9)/1000000*Assumptions!$B$46+Assumptions!$B$45/1000000*Assumptions!$B$47)*Assumptions!$B$48*(1-Assumptions!$B$49)+((IF(B9="Y1",Assumptions!$B$35,IF(B9="Y2",Assumptions!$B$36,Assumptions!$B$37)))/1000000*Assumptions!$B$39+Assumptions!$B$38/1000000*Assumptions!$B$40)*Assumptions!$B$48*Assumptions!$B$49+Assumptions!$B$56*Assumptions!$B$57)*F9*Assumptions!$B$4 -> 158.9016 | J9: =((IF(B9="Y1",Assumptions!$B$42,IF(B9="Y2",Assumptions!$B$43,Assumptions!$B$44))*(1-G9*0.9)/1000000*Assumptions!$B$46+Assumptions!$B$45/1000000*Assumptions!$B$47)*Assumptions!$B$48*(1-Assumptions!$B$49)+((IF(B9="Y1",Assumptions!$B$35,IF(B9="Y2",Assumptions!$B$36,Assumptions!$B$37)))/1000000*Assumptions!$B$39+Assumptions!$B$38/1000000*Assumptions!$B$40)*Assumptions!$B$48*Assumptions!$B$49+Assumptions!$B$56*Assumptions!$B$58)*F9*Assumptions!$B$4 -> 161.304 | K9: =C9*H9 -> 2821.104 | L9: =D9*I9 -> 14618.947 | M9: =E9*J9 -> 0 | N9: =K9+L9+M9 -> 17440.051
A10: 9 | B10: Y1 | C10: ='User Growth'!D10 -> 158 | D10: ='User Growth'!E10 -> 105 | E10: ='User Growth'!F10 -> 0 | F10: =IF(B10="Y1",Assumptions!$B$53,IF(B10="Y2",Assumptions!$B$54,Assumptions!$B$55)) -> 1 | G10: =IF(B10="Y1",Assumptions!$B$50,IF(B10="Y2",Assumptions!$B$51,Assumptions!$B$52)) -> 0 | H10: =((IF(B10="Y1",Assumptions!$B$35,IF(B10="Y2",Assumptions!$B$36,Assumptions!$B$37)))/1000000*Assumptions!$B$39+Assumptions!$B$38/1000000*Assumptions!$B$40)*F10*Assumptions!$B$41*Assumptions!$B$4 -> 20.592 | I10: =((IF(B10="Y1",Assumptions!$B$42,IF(B10="Y2",Assumptions!$B$43,Assumptions!$B$44))*(1-G10*0.9)/1000000*Assumptions!$B$46+Assumptions!$B$45/1000000*Assumptions!$B$47)*Assumptions!$B$48*(1-Assumptions!$B$49)+((IF(B10="Y1",Assumptions!$B$35,IF(B10="Y2",Assumptions!$B$36,Assumptions!$B$37)))/1000000*Assumptions!$B$39+Assumptions!$B$38/1000000*Assumptions!$B$40)*Assumptions!$B$48*Assumptions!$B$49+Assumptions!$B$56*Assumptions!$B$57)*F10*Assumptions!$B$4 -> 158.9016 | J10: =((IF(B10="Y1",Assumptions!$B$42,IF(B10="Y2",Assumptions!$B$43,Assumptions!$B$44))*(1-G10*0.9)/1000000*Assumptions!$B$46+Assumptions!$B$45/1000000*Assumptions!$B$47)*Assumptions!$B$48*(1-Assumptions!$B$49)+((IF(B10="Y1",Assumptions!$B$35,IF(B10="Y2",Assumptions!$B$36,Assumptions!$B$37)))/1000000*Assumptions!$B$39+Assumptions!$B$38/1000000*Assumptions!$B$40)*Assumptions!$B$48*Assumptions!$B$49+Assumptions!$B$56*Assumptions!$B$58)*F10*Assumptions!$B$4 -> 161.304 | K10: =C10*H10 -> 3253.536 | L10: =D10*I10 -> 16684.668 | M10: =E10*J10 -> 0 | N10: =K10+L10+M10 -> 19938.204
A11: 10 | B11: Y1 | C11: ='User Growth'!D11 -> 181 | D11: ='User Growth'!E11 -> 121 | E11: ='User Growth'!F11 -> 0 | F11: =IF(B11="Y1",Assumptions!$B$53,IF(B11="Y2",Assumptions!$B$54,Assumptions!$B$55)) -> 1 | G11: =IF(B11="Y1",Assumptions!$B$50,IF(B11="Y2",Assumptions!$B$51,Assumptions!$B$52)) -> 0 | H11: =((IF(B11="Y1",Assumptions!$B$35,IF(B11="Y2",Assumptions!$B$36,Assumptions!$B$37)))/1000000*Assumptions!$B$39+Assumptions!$B$38/1000000*Assumptions!$B$40)*F11*Assumptions!$B$41*Assumptions!$B$4 -> 20.592 | I11: =((IF(B11="Y1",Assumptions!$B$42,IF(B11="Y2",Assumptions!$B$43,Assumptions!$B$44))*(1-G11*0.9)/1000000*Assumptions!$B$46+Assumptions!$B$45/1000000*Assumptions!$B$47)*Assumptions!$B$48*(1-Assumptions!$B$49)+((IF(B11="Y1",Assumptions!$B$35,IF(B11="Y2",Assumptions!$B$36,Assumptions!$B$37)))/1000000*Assumptions!$B$39+Assumptions!$B$38/1000000*Assumptions!$B$40)*Assumptions!$B$48*Assumptions!$B$49+Assumptions!$B$56*Assumptions!$B$57)*F11*Assumptions!$B$4 -> 158.9016 | J11: =((IF(B11="Y1",Assumptions!$B$42,IF(B11="Y2",Assumptions!$B$43,Assumptions!$B$44))*(1-G11*0.9)/1000000*Assumptions!$B$46+Assumptions!$B$45/1000000*Assumptions!$B$47)*Assumptions!$B$48*(1-Assumptions!$B$49)+((IF(B11="Y1",Assumptions!$B$35,IF(B11="Y2",Assumptions!$B$36,Assumptions!$B$37)))/1000000*Assumptions!$B$39+Assumptions!$B$38/1000000*Assumptions!$B$40)*Assumptions!$B$48*Assumptions!$B$49+Assumptions!$B$56*Assumptions!$B$58)*F11*Assumptions!$B$4 -> 161.304 | K11: =C11*H11 -> 3727.152 | L11: =D11*I11 -> 19227.094 | M11: =E11*J11 -> 0 | N11: =K11+L11+M11 -> 22954.246
A12: 11 | B12: Y1 | C12: ='User Growth'!D12 -> 208 | D12: ='User Growth'!E12 -> 139 | E12: ='User Growth'!F12 -> 0 | F12: =IF(B12="Y1",Assumptions!$B$53,IF(B12="Y2",Assumptions!$B$54,Assumptions!$B$55)) -> 1 | G12: =IF(B12="Y1",Assumptions!$B$50,IF(B12="Y2",Assumptions!$B$51,Assumptions!$B$52)) -> 0 | H12: =((IF(B12="Y1",Assumptions!$B$35,IF(B12="Y2",Assumptions!$B$36,Assumptions!$B$37)))/1000000*Assumptions!$B$39+Assumptions!$B$38/1000000*Assumptions!$B$40)*F12*Assumptions!$B$41*Assumptions!$B$4 -> 20.592 | I12: =((IF(B12="Y1",Assumptions!$B$42,IF(B12="Y2",Assumptions!$B$43,Assumptions!$B$44))*(1-G12*0.9)/1000000*Assumptions!$B$46+Assumptions!$B$45/1000000*Assumptions!$B$47)*Assumptions!$B$48*(1-Assumptions!$B$49)+((IF(B12="Y1",Assumptions!$B$35,IF(B12="Y2",Assumptions!$B$36,Assumptions!$B$37)))/1000000*Assumptions!$B$39+Assumptions!$B$38/1000000*Assumptions!$B$40)*Assumptions!$B$48*Assumptions!$B$49+Assumptions!$B$56*Assumptions!$B$57)*F12*Assumptions!$B$4 -> 158.9016 | J12: =((IF(B12="Y1",Assumptions!$B$42,IF(B12="Y2",Assumptions!$B$43,Assumptions!$B$44))*(1-G12*0.9)/1000000*Assumptions!$B$46+Assumptions!$B$45/1000000*Assumptions!$B$47)*Assumptions!$B$48*(1-Assumptions!$B$49)+((IF(B12="Y1",Assumptions!$B$35,IF(B12="Y2",Assumptions!$B$36,Assumptions!$B$37)))/1000000*Assumptions!$B$39+Assumptions!$B$38/1000000*Assumptions!$B$40)*Assumptions!$B$48*Assumptions!$B$49+Assumptions!$B$56*Assumptions!$B$58)*F12*Assumptions!$B$4 -> 161.304 | K12: =C12*H12 -> 4283.136 | L12: =D12*I12 -> 22087.322 | M12: =E12*J12 -> 0 | N12: =K12+L12+M12 -> 26370.458
A13: 12 | B13: Y1 | C13: ='User Growth'!D13 -> 239 | D13: ='User Growth'!E13 -> 160 | E13: ='User Growth'!F13 -> 0 | F13: =IF(B13="Y1",Assumptions!$B$53,IF(B13="Y2",Assumptions!$B$54,Assumptions!$B$55)) -> 1 | G13: =IF(B13="Y1",Assumptions!$B$50,IF(B13="Y2",Assumptions!$B$51,Assumptions!$B$52)) -> 0 | H13: =((IF(B13="Y1",Assumptions!$B$35,IF(B13="Y2",Assumptions!$B$36,Assumptions!$B$37)))/1000000*Assumptions!$B$39+Assumptions!$B$38/1000000*Assumptions!$B$40)*F13*Assumptions!$B$41*Assumptions!$B$4 -> 20.592 | I13: =((IF(B13="Y1",Assumptions!$B$42,IF(B13="Y2",Assumptions!$B$43,Assumptions!$B$44))*(1-G13*0.9)/1000000*Assumptions!$B$46+Assumptions!$B$45/1000000*Assumptions!$B$47)*Assumptions!$B$48*(1-Assumptions!$B$49)+((IF(B13="Y1",Assumptions!$B$35,IF(B13="Y2",Assumptions!$B$36,Assumptions!$B$37)))/1000000*Assumptions!$B$39+Assumptions!$B$38/1000000*Assumptions!$B$40)*Assumptions!$B$48*Assumptions!$B$49+Assumptions!$B$56*Assumptions!$B$57)*F13*Assumptions!$B$4 -> 158.9016 | J13: =((IF(B13="Y1",Assumptions!$B$42,IF(B13="Y2",Assumptions!$B$43,Assumptions!$B$44))*(1-G13*0.9)/1000000*Assumptions!$B$46+Assumptions!$B$45/1000000*Assumptions!$B$47)*Assumptions!$B$48*(1-Assumptions!$B$49)+((IF(B13="Y1",Assumptions!$B$35,IF(B13="Y2",Assumptions!$B$36,Assumptions!$B$37)))/1000000*Assumptions!$B$39+Assumptions!$B$38/1000000*Assumptions!$B$40)*Assumptions!$B$48*Assumptions!$B$49+Assumptions!$B$56*Assumptions!$B$58)*F13*Assumptions!$B$4 -> 161.304 | K13: =C13*H13 -> 4921.488 | L13: =D13*I13 -> 25424.256 | M13: =E13*J13 -> 0 | N13: =K13+L13+M13 -> 30345.744
... A37: 36 | B37: Y3 | C37: ='User Growth'!D37 -> 1733 | D37: ='User Growth'!E37 -> 1197 | E37: ='User Growth'!F37 -> 221 | F37: =IF(B37="Y1",Assumptions!$B$53,IF(B37="Y2",Assumptions!$B$54,Assumptions!$B$55)) -> 1.65 | G37: =IF(B37="Y1",Assumptions!$B$50,IF(B37="Y2",Assumptions!$B$51,Assumptions!$B$52)) -> 0.6 | H37: =((IF(B37="Y1",Assumptions!$B$35,IF(B37="Y2",Assumptions!$B$36,Assumptions!$B$37)))/1000000*Assumptions!$B$39+Assumptions!$B$38/1000000*Assumptions!$B$40)*F37*Assumptions!$B$41*Assumptions!$B$4 -> 43.03728 | I37: =((IF(B37="Y1",Assumptions!$B$42,IF(B37="Y2",Assumptions!$B$43,Assumptions!$B$44))*(1-G37*0.9)/1000000*Assumptions!$B$46+Assumptions!$B$45/1000000*Assumptions!$B$47)*Assumptions!$B$48*(1-Assumptions!$B$49)+((IF(B37="Y1",Assumptions!$B$35,IF(B37="Y2",Assumptions!$B$36,Assumptions!$B$37)))/1000000*Assumptions!$B$39+Assumptions!$B$38/1000000*Assumptions!$B$40)*Assumptions!$B$48*Assumptions!$B$49+Assumptions!$B$56*Assumptions!$B$57)*F37*Assumptions!$B$4 -> 246.69422 | J37: =((IF(B37="Y1",Assumptions!$B$42,IF(B37="Y2",Assumptions!$B$43,Assumptions!$B$44))*(1-G37*0.9)/1000000*Assumptions!$B$46+Assumptions!$B$45/1000000*Assumptions!$B$47)*Assumptions!$B$48*(1-Assumptions!$B$49)+((IF(B37="Y1",Assumptions!$B$35,IF(B37="Y2",Assumptions!$B$36,Assumptions!$B$37)))/1000000*Assumptions!$B$39+Assumptions!$B$38/1000000*Assumptions!$B$40)*Assumptions!$B$48*Assumptions!$B$49+Assumptions!$B$56*Assumptions!$B$58)*F37*Assumptions!$B$4 -> 250.65818 | K37: =C37*H37 -> 74583.606 | L37: =D37*I37 -> 295292.98 | M37: =E37*J37 -> 55395.458 | N37: =K37+L37+M37 -> 425272.04

Sheet Fixed OpEx
A1: Month | B1: Year | C1: Hosting | D1: Database | E1: WhatsApp | F1: Monitoring | G1: Email | H1: Domain/SSL | I1: Misc | J1: TOTAL OpEx
A2: 1 | B2: Y1 | C2: =IF(A2<=6,Assumptions!$B$68,Assumptions!$B$69) -> 0 | D2: =IF(A2<=9,Assumptions!$B$70,Assumptions!$B$71) -> 0 | E2: =IF(A2<=6,Assumptions!$B$72,Assumptions!$B$73) -> 0 | F2: =Assumptions!$B$74 -> 0 | G2: =Assumptions!$B$75 -> 0 | H2: =Assumptions!$B$76 -> 500 | I2: =Assumptions!$B$77 -> 500 | J2: =SUM(C2:I2) -> 1000
A3: 2 | B3: Y1 | C3: =IF(A3<=6,Assumptions!$B$68,Assumptions!$B$69) -> 0 | D3: =IF(A3<=9,Assumptions!$B$70,Assumptions!$B$71) -> 0 | E3: =IF(A3<=6,Assumptions!$B$72,Assumptions!$B$73) -> 0 | F3: =Assumptions!$B$74 -> 0 | G3: =Assumptions!$B$75 -> 0 | H3: =Assumptions!$B$76 -> 500 | I3: =Assumptions!$B$77 -> 500 | J3: =SUM(C3:I3) -> 1000
A4: 3 | B4: Y1 | C4: =IF(A4<=6,Assumptions!$B$68,Assumptions!$B$69) -> 0 | D4: =IF(A4<=9,Assumptions!$B$70,Assumptions!$B$71) -> 0 | E4: =IF(A4<=6,Assumptions!$B$72,Assumptions!$B$73) -> 0 | F4: =Assumptions!$B$74 -> 0 | G4: =Assumptions!$B$75 -> 0 | H4: =Assumptions!$B$76 -> 500 | I4: =Assumptions!$B$77 -> 500 | J4: =SUM(C4:I4) -> 1000
A5: 4 | B5: Y1 | C5: =IF(A5<=6,Assumptions!$B$68,Assumptions!$B$69) -> 0 | D5: =IF(A5<=9,Assumptions!$B$70,Assumptions!$B$71) -> 0 | E5: =IF(A5<=6,Assumptions!$B$72,Assumptions!$B$73) -> 0 | F5: =Assumptions!$B$74 -> 0 | G5: =Assumptions!$B$75 -> 0 | H5: =Assumptions!$B$76 -> 500 | I5: =Assumptions!$B$77 -> 500 | J5: =SUM(C5:I5) -> 1000
A6: 5 | B6: Y1 | C6: =IF(A6<=6,Assumptions!$B$68,Assumptions!$B$69) -> 0 | D6: =IF(A6<=9,Assumptions!$B$70,Assumptions!$B$71) -> 0 | E6: =IF(A6<=6,Assumptions!$B$72,Assumptions!$B$73) -> 0 | F6: =Assumptions!$B$74 -> 0 | G6: =Assumptions!$B$75 -> 0 | H6: =Assumptions!$B$76 -> 500 | I6: =Assumptions!$B$77 -> 500 | J6: =SUM(C6:I6) -> 1000
A7: 6 | B7: Y1 | C7: =IF(A7<=6,Assumptions!$B$68,Assumptions!$B$69) -> 0 | D7: =IF(A7<=9,Assumptions!$B$70,Assumptions!$B$71) -> 0 | E7: =IF(A7<=6,Assumptions!$B$72,Assumptions!$B$73) -> 0 | F7: =Assumptions!$B$74 -> 0 | G7: =Assumptions!$B$75 -> 0 | H7: =Assumptions!$B$76 -> 500 | I7: =Assumptions!$B$77 -> 500 | J7: =SUM(C7:I7) -> 1000
A8: 7 | B8: Y1 | C8: =IF(A8<=6,Assumptions!$B$68,Assumptions!$B$69) -> 286 | D8: =IF(A8<=9,Assumptions!$B$70,Assumptions!$B$71) -> 0 | E8: =IF(A8<=6,Assumptions!$B$72,Assumptions!$B$73) -> 572 | F8: =Assumptions!$B$74 -> 0 | G8: =Assumptions!$B$75 -> 0 | H8: =Assumptions!$B$76 -> 500 | I8: =Assumptions!$B$77 -> 500 | J8: =SUM(C8:I8) -> 1858
A9: 8 | B9: Y1 | C9: =IF(A9<=6,Assumptions!$B$68,Assumptions!$B$69) -> 286 | D9: =IF(A9<=9,Assumptions!$B$70,Assumptions!$B$71) -> 0 | E9: =IF(A9<=6,Assumptions!$B$72,Assumptions!$B$73) -> 572 | F9: =Assumptions!$B$74 -> 0 | G9: =Assumptions!$B$75 -> 0 | H9: =Assumptions!$B$76 -> 500 | I9: =Assumptions!$B$77 -> 500 | J9: =SUM(C9:I9) -> 1858
A10: 9 | B10: Y1 | C10: =IF(A10<=6,Assumptions!$B$68,Assumptions!$B$69) -> 286 | D10: =IF(A10<=9,Assumptions!$B$70,Assumptions!$B$71) -> 0 | E10: =IF(A10<=6,Assumptions!$B$72,Assumptions!$B$73) -> 572 | F10: =Assumptions!$B$74 -> 0 | G10: =Assumptions!$B$75 -> 0 | H10: =Assumptions!$B$76 -> 500 | I10: =Assumptions!$B$77 -> 500 | J10: =SUM(C10:I10) -> 1858
A11: 10 | B11: Y1 | C11: =IF(A11<=6,Assumptions!$B$68,Assumptions!$B$69) -> 286 | D11: =IF(A11<=9,Assumptions!$B$70,Assumptions!$B$71) -> 1430 | E11: =IF(A11<=6,Assumptions!$B$72,Assumptions!$B$73) -> 572 | F11: =Assumptions!$B$74 -> 0 | G11: =Assumptions!$B$75 -> 0 | H11: =Assumptions!$B$76 -> 500 | I11: =Assumptions!$B$77 -> 500 | J11: =SUM(C11:I11) -> 3288
A12: 11 | B12: Y1 | C12: =IF(A12<=6,Assumptions!$B$68,Assumptions!$B$69) -> 286 | D12: =IF(A12<=9,Assumptions!$B$70,Assumptions!$B$71) -> 1430 | E12: =IF(A12<=6,Assumptions!$B$72,Assumptions!$B$73) -> 572 | F12: =Assumptions!$B$74 -> 0 | G12: =Assumptions!$B$75 -> 0 | H12: =Assumptions!$B$76 -> 500 | I12: =Assumptions!$B$77 -> 500 | J12: =SUM(C12:I12) -> 3288
A13: 12 | B13: Y1 | C13: =IF(A13<=6,Assumptions!$B$68,Assumptions!$B$69) -> 286 | D13: =IF(A13<=9,Assumptions!$B$70,Assumptions!$B$71) -> 1430 | E13: =IF(A13<=6,Assumptions!$B$72,Assumptions!$B$73) -> 572 | F13: =Assumptions!$B$74 -> 0 | G13: =Assumptions!$B$75 -> 0 | H13: =Assumptions!$B$76 -> 500 | I13: =Assumptions!$B$77 -> 500 | J13: =SUM(C13:I13) -> 3288
... A37: 36 | B37: Y3 | C37: =IF(A37<=6,Assumptions!$B$68,Assumptions!$B$69) -> 286 | D37: =IF(A37<=9,Assumptions!$B$70,Assumptions!$B$71) -> 1430 | E37: =IF(A37<=6,Assumptions!$B$72,Assumptions!$B$73) -> 572 | F37: =Assumptions!$B$74 -> 0 | G37: =Assumptions!$B$75 -> 0 | H37: =Assumptions!$B$76 -> 500 | I37: =Assumptions!$B$77 -> 500 | J37: =SUM(C37:I37) -> 3288

Sheet P&L
A1: AKBai — Profit & Loss Summary
B3: Y1 (2026) | C3: Y2 (2027) | D3: Y3 (2028)
A4: REVENUE
A5: Beta Revenue | B5: =SUMIF(Revenue!B:B,"Y1",Revenue!C:C) -> 29800 | C5: =SUMIF(Revenue!B:B,"Y2",Revenue!C:C) -> 0 | D5: =SUMIF(Revenue!B:B,"Y3",Revenue!C:C) -> 0
A6: Pro Revenue | B6: =SUMIF(Revenue!B:B,"Y1",Revenue!D:D) -> 246974 | C6: =SUMIF(Revenue!B:B,"Y2",Revenue!D:D) -> 1068626 | D6: =SUMIF(Revenue!B:B,"Y3",Revenue!D:D) -> 2917044
A7: Business Revenue | B7: =SUMIF(Revenue!B:B,"Y1",Revenue!E:E) -> 0 | C7: =SUMIF(Revenue!B:B,"Y2",Revenue!E:E) -> 527340 | D7: =SUMIF(Revenue!B:B,"Y3",Revenue!E:E) -> 1435004
A8: Gross Revenue | B8: =B5+B6+B7 -> 276774 | C8: =C5+C6+C7 -> 1595966 | D8: =D5+D6+D7 -> 4352048
A9: Less: Xendit Fees | B9: =SUMIF(Revenue!B:B,"Y1",Revenue!G:G) -> 5258.706 | C9: =SUMIF(Revenue!B:B,"Y2",Revenue!G:G) -> 30323.354 | D9: =SUMIF(Revenue!B:B,"Y3",Revenue!G:G) -> 82688.912
A10: NET REVENUE | B10: =B8-B9 -> 271515.29 | C10: =C8-C9 -> 1565642.6 | D10: =D8-D9 -> 4269359.1
A12: VARIABLE COSTS (API)
A13: API Costs — Free tier | B13: =SUMIF('API Costs'!B:B,"Y1",'API Costs'!K:K) -> 25451.712 | C13: =SUMIF('API Costs'!B:B,"Y2",'API Costs'!K:K) -> 162947.79 | D13: =SUMIF('API Costs'!B:B,"Y3",'API Costs'!K:K) -> 607815.51
A14: API Costs — Pro tier | B14: =SUMIF('API Costs'!B:B,"Y1",'API Costs'!L:L) -> 131252.72 | C14: =SUMIF('API Costs'!B:B,"Y2",'API Costs'!L:L) -> 735685.78 | D14: =SUMIF('API Costs'!B:B,"Y3",'API Costs'!L:L) -> 2406748.8
A15: API Costs — Business tier | B15: =SUMIF('API Costs'!B:B,"Y1",'API Costs'!M:M) -> 0 | C15: =SUMIF('API Costs'!B:B,"Y2",'API Costs'!M:M) -> 137997.45 | D15: =SUMIF('API Costs'!B:B,"Y3",'API Costs'!M:M) -> 450182.09
A16: TOTAL VARIABLE COSTS | B16: =B13+B14+B15 -> 156704.43 | C16: =C13+C14+C15 -> 1036631 | D16: =D13+D14+D15 -> 3464746.4
A18: GROSS PROFIT | B18: =B10-B16 -> 114810.86 | C18: =C10-C16 -> 529011.63 | D18: =D10-D16 -> 804612.69
A19: Gross Margin % | B19: =IF(B10=0,0,B18/B10) -> 0.42285228 | C19: =IF(C10=0,0,C18/C10) -> 0.33788785 | D19: =IF(D10=0,0,D18/D10) -> 0.18846217
A21: FIXED OPERATING EXPENSES
A22: Total Fixed OpEx | B22: =SUMIF('Fixed OpEx'!B:B,"Y1",'Fixed OpEx'!J:J) -> 21438 | C22: =SUMIF('Fixed OpEx'!B:B,"Y2",'Fixed OpEx'!J:J) -> 39456 | D22: =SUMIF('Fixed OpEx'!B:B,"Y3",'Fixed OpEx'!J:J) -> 39456
A24: EBITDA | B24: =B18-B22 -> 93372.86 | C24: =C18-C22 -> 489555.63 | D24: =D18-D22 -> 765156.69
A25: EBITDA Margin % | B25: =IF(B10=0,0,B24/B10) -> 0.3438954 | C25: =IF(C10=0,0,C24/C10) -> 0.3126867 | D25: =IF(D10=0,0,D24/D10) -> 0.1792205
A27: ONE-TIME COSTS
A28: CapEx (one-time, Y1 only) | B28: =Assumptions!$B$90 -> 28800 | C28: 0 | D28: 0
A29: UAT Cost (pre-launch, Y1 only) | B29: =Assumptions!$B$82 -> 800 | C29: 0 | D29: 0
A31: NET PROFIT / (LOSS) | B31: =B24-B28-B29 -> 63772.86 | C31: =C24-C28-C29 -> 489555.63 | D31: =D24-D28-D29 -> 765156.69
A32: Net Margin % | B32: =IF(B10=0,0,B31/B10) -> 0.2348776 | C32: =IF(C10=0,0,C31/C10) -> 0.3126867 | D32: =IF(D10=0,0,D31/D10) -> 0.1792205

Sheet Break-Even
A1: Month | B1: Year | C1: Net Revenue | D1: API Costs | E1: Fixed OpEx | F1: Total Costs | G1: Monthly Profit | H1: Cumulative Profit | I1: Break-Even? | K1: Break-Even Analysis
A2: 1 | B2: Y1 | C2: =Revenue!H2 -> 2923.38 | D2: ='API Costs'!N2 -> 0 | E2: ='Fixed OpEx'!J2 -> 1000 | F2: =D2+E2 -> 1000 | G2: =C2-F2 -> 1923.38 | H2: =G2-Assumptions!$B$90-Assumptions!$B$82 -> -27676.62 | I2: =IF(AND(H2>0,H1<=0),"✓ BREAK-EVEN",IF(H2>0,"▲ Profitable","")) | K2: Break-Even Month: | L2: =IFERROR(MATCH(TRUE(),H2:H37>0,0),"Not yet") -> 5
A3: 2 | B3: Y1 | C3: =Revenue!H3 -> 5846.76 | D3: ='API Costs'!N3 -> 0 | E3: ='Fixed OpEx'!J3 -> 1000 | F3: =D3+E3 -> 1000 | G3: =C3-F3 -> 4846.76 | H3: =H2+G3 -> -22829.86 | I3: =IF(AND(H3>0,H2<=0),"✓ BREAK-EVEN",IF(H3>0,"▲ Profitable","")) | K3: First profitable month: | L3: =IFERROR(INDEX(A2:A37,MATCH(TRUE(),H2:H37>0,0)),"—") -> 5
A4: 3 | B4: Y1 | C4: =Revenue!H4 -> 8770.14 | D4: ='API Costs'!N4 -> 0 | E4: ='Fixed OpEx'!J4 -> 1000 | F4: =D4+E4 -> 1000 | G4: =C4-F4 -> 7770.14 | H4: =H3+G4 -> -15059.72 | I4: =IF(AND(H4>0,H3<=0),"✓ BREAK-EVEN",IF(H4>0,"▲ Profitable",""))
A5: 4 | B5: Y1 | C5: =Revenue!H5 -> 11693.52 | D5: ='API Costs'!N5 -> 0 | E5: ='Fixed OpEx'!J5 -> 1000 | F5: =D5+E5 -> 1000 | G5: =C5-F5 -> 10693.52 | H5: =H4+G5 -> -4366.2 | I5: =IF(AND(H5>0,H4<=0),"✓ BREAK-EVEN",IF(H5>0,"▲ Profitable",""))
A6: 5 | B6: Y1 | C6: =Revenue!H6 -> 17599.14 | D6: ='API Costs'!N6 -> 11387.376 | E6: ='Fixed OpEx'!J6 -> 1000 | F6: =D6+E6 -> 12387.376 | G6: =C6-F6 -> 5211.764 | H6: =H5+G6 -> 845.564 | I6: =IF(AND(H6>0,H5<=0),"✓ BREAK-EVEN",IF(H6>0,"▲ Profitable","")) -> ✓ BREAK-EVEN
A7: 6 | B7: Y1 | C7: =Revenue!H7 -> 20239.011 | D7: ='API Costs'!N7 -> 13105.778 | E7: ='Fixed OpEx'!J7 -> 1000 | F7: =D7+E7 -> 14105.778 | G7: =C7-F7 -> 6133.2326 | H7: =H6+G7 -> 6978.7966 | I7: =IF(AND(H7>0,H6<=0),"✓ BREAK-EVEN",IF(H7>0,"▲ Profitable","")) -> ▲ Profitable
A8: 7 | B8: Y1 | C8: =Revenue!H8 -> 23465.52 | D8: ='API Costs'!N8 -> 15162.576 | E8: ='Fixed OpEx'!J8 -> 1858 | F8: =D8+E8 -> 17020.576 | G8: =C8-F8 -> 6444.944 | H8: =H7+G8 -> 13423.741 | I8: =IF(AND(H8>0,H7<=0),"✓ BREAK-EVEN",IF(H8>0,"▲ Profitable","")) -> ▲ Profitable
A9: 8 | B9: Y1 | C9: =Revenue!H9 -> 26985.348 | D9: ='API Costs'!N9 -> 17440.051 | E9: ='Fixed OpEx'!J9 -> 1858 | F9: =D9+E9 -> 19298.051 | G9: =C9-F9 -> 7687.2968 | H9: =H8+G9 -> 21111.037 | I9: =IF(AND(H9>0,H8<=0),"✓ BREAK-EVEN",IF(H9>0,"▲ Profitable","")) -> ▲ Profitable
A10: 9 | B10: Y1 | C10: =Revenue!H10 -> 30798.495 | D10: ='API Costs'!N10 -> 19938.204 | E10: ='Fixed OpEx'!J10 -> 1858 | F10: =D10+E10 -> 21796.204 | G10: =C10-F10 -> 9002.291 | H10: =H9+G10 -> 30113.328 | I10: =IF(AND(H10>0,H9<=0),"✓ BREAK-EVEN",IF(H10>0,"▲ Profitable","")) -> ▲ Profitable
A11: 10 | B11: Y1 | C11: =Revenue!H11 -> 35491.599 | D11: ='API Costs'!N11 -> 22954.246 | E11: ='Fixed OpEx'!J11 -> 3288 | F11: =D11+E11 -> 26242.246 | G11: =C11-F11 -> 9249.3534 | H11: =H10+G11 -> 39362.682 | I11: =IF(AND(H11>0,H10<=0),"✓ BREAK-EVEN",IF(H11>0,"▲ Profitable","")) -> ▲ Profitable
A12: 11 | B12: Y1 | C12: =Revenue!H12 -> 40771.341 | D12: ='API Costs'!N12 -> 26370.458 | E12: ='Fixed OpEx'!J12 -> 3288 | F12: =D12+E12 -> 29658.458 | G12: =C12-F12 -> 11112.883 | H12: =H11+G12 -> 50475.564 | I12: =IF(AND(H12>0,H11<=0),"✓ BREAK-EVEN",IF(H12>0,"▲ Profitable","")) -> ▲ Profitable
A13: 12 | B13: Y1 | C13: =Revenue!H13 -> 46931.04 | D13: ='API Costs'!N13 -> 30345.744 | E13: ='Fixed OpEx'!J13 -> 3288 | F13: =D13+E13 -> 33633.744 | G13: =C13-F13 -> 13297.296 | H13: =H12+G13 -> 63772.86 | I13: =IF(AND(H13>0,H12<=0),"✓ BREAK-EVEN",IF(H13>0,"▲ Profitable","")) -> ▲ Profitable
A14: 13 | B14: Y2 | C14: =Revenue!H14 -> 73282.662 | D14: ='API Costs'!N14 -> 48450.503 | E14: ='Fixed OpEx'!J14 -> 3288 | F14: =D14+E14 -> 51738.503 | G14: =C14-F14 -> 21544.159 | H14: =H13+G14 -> 85317.019 | I14: =IF(AND(H14>0,H13<=0),"✓ BREAK-EVEN",IF(H14>0,"▲ Profitable","")) -> ▲ Profitable
A15: 14 | B15: Y2 | C15: =Revenue!H15 -> 80620.542 | D15: ='API Costs'!N15 -> 53364.753 | E15: ='Fixed OpEx'!J15 -> 3288 | F15: =D15+E15 -> 56652.753 | G15: =C15-F15 -> 23967.789 | H15: =H14+G15 -> 109284.81 | I15: =IF(AND(H15>0,H14<=0),"✓ BREAK-EVEN",IF(H15>0,"▲ Profitable","")) -> ▲ Profitable
... A37: 36 | B37: Y3 | C37: =Revenue!H37 -> 524326.84 | D37: ='API Costs'!N37 -> 425272.04 | E37: ='Fixed OpEx'!J37 -> 3288 | F37: =D37+E37 -> 428560.04 | G37: =C37-F37 -> 95766.798 | H37: =H36+G37 -> 1318485.2 | I37: =IF(AND(H37>0,H36<=0),"✓ BREAK-EVEN",IF(H37>0,"▲ Profitable","")) -> ▲ Profitable

Sheet Dashboard
A1: AKBai — Financial Dashboard
A2: Note: AKBai uses the Claude API (pay-per-token). No weekly message limits apply. Free tier 10q/day cap is AKBai's own cost control.
B4: Y1 (2026) | C4: Y2 (2027) | D4: Y3 (2028) | G4: Y1 (2026) | H4: Y2 (2027) | I4: Y3 (2028)
A5: 👥 Total Active Users (End of Year)
A6: End-Year MAU | B6: ='User Growth'!G13 -> 399 | C6: ='User Growth'!G25 -> 1256 | D6: ='User Growth'!G37 -> 3151
A7: — Pro Users | B7: ='User Growth'!E13 -> 160 | C7: ='User Growth'!E25 -> 477 | D7: ='User Growth'!E37 -> 1197
A9: ₱ Revenue
A10: Gross Revenue | B10: =SUMIF(Revenue!B:B,"Y1",Revenue!F:F) -> 276774 | C10: =SUMIF(Revenue!B:B,"Y2",Revenue!F:F) -> 1595966 | D10: =SUMIF(Revenue!B:B,"Y3",Revenue!F:F) -> 4352048
A11: Net Revenue | B11: ='P&L'!B10 -> 271515.29 | C11: ='P&L'!C10 -> 1565642.6 | D11: ='P&L'!D10 -> 4269359.1
A13: 💸 Total API Costs
B14: =SUMIF('API Costs'!B:B,"Y1",'API Costs'!N:N) -> 156704.43 | C14: =SUMIF('API Costs'!B:B,"Y2",'API Costs'!N:N) -> 1036631 | D14: =SUMIF('API Costs'!B:B,"Y3",'API Costs'!N:N) -> 3464746.4
A16: 📈 Gross Profit & Net Profit
A17: Gross Profit | B17: ='P&L'!B18 -> 114810.86 | C17: ='P&L'!C18 -> 529011.63 | D17: ='P&L'!D18 -> 804612.69
A18: EBITDA | B18: ='P&L'!B24 -> 93372.86 | C18: ='P&L'!C24 -> 489555.63 | D18: ='P&L'!D24 -> 765156.69
A19: NET PROFIT / (LOSS) | B19: ='P&L'!B31 -> 63772.86 | C19: ='P&L'!C31 -> 489555.63 | D19: ='P&L'!D31 -> 765156.69
A21: 🎯 Break-Even
A22: Break-Even Month # | B22: =IFERROR(MATCH(TRUE(),'Break-Even'!H2:H37>0,0),"Not in Y1-Y3") -> 5
A24: 🔬 Unit Economics (Y1)
A25: Free user API cost/month | B25: =Assumptions!$B$95 -> 20.592
A26: Pro user API cost/month | B26: =Assumptions!$B$96 -> 158.9016
A27: Pro price | B27: =Assumptions!$B$30 -> 299
A28: Pro gross margin/user | B28: =Assumptions!$B$30-Assumptions!$B$96 -> 140.0984
A29: Pro gross margin % | B29: =IF(Assumptions!$B$30=0,0,(Assumptions!$B$30-Assumptions!$B$96)/Assumptions!$B$30) -> 0.46855652
