Workbook

Sheet Dashboard
A1: AKBai Financial Model - Dashboard
A3: Key Metrics
A4: Metric | B4: Year 1 | C4: Year 2 | D4: Year 3
A5: Total Users | B5: ='User Growth'!C30 -> 122 | C5: ='User Growth'!C42 -> 422 | D5: ='User Growth'!C54 -> 1742
A6: Paying Users | B6: ='User Growth'!C30 -> 122 | C6: ='User Growth'!C42 -> 422 | D6: ='User Growth'!C54 -> 1742
A7: Total Revenue (₱) | B7: ='User Growth'!C30 -> 122 | C7: ='User Growth'!C42 -> 422 | D7: ='User Growth'!C54 -> 1742
A8: Net Profit (₱) | B8: ='User Growth'!C30 -> 122 | C8: ='User Growth'!C42 -> 422 | D8: ='User Growth'!C54 -> 1742
A9: Break-Even Month | B9: ='User Growth'!C30 -> 122 | C9: ='User Growth'!C42 -> 422 | D9: ='User Growth'!C54 -> 1742

Sheet User Growth
A1: User Growth Model (36 Months)
A3: Assumptions
A4: Launch Total (M1) | B4: 10
A5: M1-6 New/Mo | B5: 8
A6: M7-12 New/Mo | B6: 12
A7: Y2 New/Mo | B7: 25
A8: Y3 New/Mo | B8: 110
A9: Free Churn | B9: 0.08
A10: Paid Churn | B10: 0.05
A11: Free % Y1 | B11: 0.67
A12: Pro % Y1 | B12: 0.33
A13: Free % Y2+ | B13: 0.62
A14: Pro % Y2+ | B14: 0.33
A15: Business % Y2+ | B15: 0.05
A18: Month | B18: Year | C18: Total | D18: Free | E18: Pro | F18: Business
A19: 1 | B19: =INT((A19-1)/12)+1 -> 1 | C19: 10 | D19: =C19*$B$8 -> 1100 | E19: =C19*$B$9 -> 0.8 | F19: 0
A20: 2 | B20: =INT((A20-1)/12)+1 -> 1 | C20: =C19+8 -> 18 | D20: =C20*$B$8 -> 1980 | E20: =C20*$B$9 -> 1.44 | F20: 0
A21: 3 | B21: =INT((A21-1)/12)+1 -> 1 | C21: =C20+8 -> 26 | D21: =C21*$B$8 -> 2860 | E21: =C21*$B$9 -> 2.08 | F21: 0
A22: 4 | B22: =INT((A22-1)/12)+1 -> 1 | C22: =C21+8 -> 34 | D22: =C22*$B$8 -> 3740 | E22: =C22*$B$9 -> 2.72 | F22: 0
A23: 5 | B23: =INT((A23-1)/12)+1 -> 1 | C23: =C22+8 -> 42 | D23: =C23*$B$8 -> 4620 | E23: =C23*$B$9 -> 3.36 | F23: 0
A24: 6 | B24: =INT((A24-1)/12)+1 -> 1 | C24: =C23+8 -> 50 | D24: =C24*$B$8 -> 5500 | E24: =C24*$B$9 -> 4 | F24: 0
A25: 7 | B25: =INT((A25-1)/12)+1 -> 1 | C25: =C24+12 -> 62 | D25: =C25*$B$8 -> 6820 | E25: =C25*$B$9 -> 4.96 | F25: 0
A26: 8 | B26: =INT((A26-1)/12)+1 -> 1 | C26: =C25+12 -> 74 | D26: =C26*$B$8 -> 8140 | E26: =C26*$B$9 -> 5.92 | F26: 0
A27: 9 | B27: =INT((A27-1)/12)+1 -> 1 | C27: =C26+12 -> 86 | D27: =C27*$B$8 -> 9460 | E27: =C27*$B$9 -> 6.88 | F27: 0
A28: 10 | B28: =INT((A28-1)/12)+1 -> 1 | C28: =C27+12 -> 98 | D28: =C28*$B$8 -> 10780 | E28: =C28*$B$9 -> 7.84 | F28: 0
A29: 11 | B29: =INT((A29-1)/12)+1 -> 1 | C29: =C28+12 -> 110 | D29: =C29*$B$8 -> 12100 | E29: =C29*$B$9 -> 8.8 | F29: 0
A30: 12 | B30: =INT((A30-1)/12)+1 -> 1 | C30: =C29+12 -> 122 | D30: =C30*$B$8 -> 13420 | E30: =C30*$B$9 -> 9.76 | F30: 0
A31: 13 | B31: =INT((A31-1)/12)+1 -> 2 | C31: =C30+25 -> 147 | D31: =C31*$B$10 -> 7.35 | E31: =C31*$B$11 -> 98.49 | F31: =C31*$B$12 -> 48.51
A32: 14 | B32: =INT((A32-1)/12)+1 -> 2 | C32: =C31+25 -> 172 | D32: =C32*$B$10 -> 8.6 | E32: =C32*$B$11 -> 115.24 | F32: =C32*$B$12 -> 56.76
A33: 15 | B33: =INT((A33-1)/12)+1 -> 2 | C33: =C32+25 -> 197 | D33: =C33*$B$10 -> 9.85 | E33: =C33*$B$11 -> 131.99 | F33: =C33*$B$12 -> 65.01
A34: 16 | B34: =INT((A34-1)/12)+1 -> 2 | C34: =C33+25 -> 222 | D34: =C34*$B$10 -> 11.1 | E34: =C34*$B$11 -> 148.74 | F34: =C34*$B$12 -> 73.26
A35: 17 | B35: =INT((A35-1)/12)+1 -> 2 | C35: =C34+25 -> 247 | D35: =C35*$B$10 -> 12.35 | E35: =C35*$B$11 -> 165.49 | F35: =C35*$B$12 -> 81.51
A36: 18 | B36: =INT((A36-1)/12)+1 -> 2 | C36: =C35+25 -> 272 | D36: =C36*$B$10 -> 13.6 | E36: =C36*$B$11 -> 182.24 | F36: =C36*$B$12 -> 89.76
A37: 19 | B37: =INT((A37-1)/12)+1 -> 2 | C37: =C36+25 -> 297 | D37: =C37*$B$10 -> 14.85 | E37: =C37*$B$11 -> 198.99 | F37: =C37*$B$12 -> 98.01
A38: 20 | B38: =INT((A38-1)/12)+1 -> 2 | C38: =C37+25 -> 322 | D38: =C38*$B$10 -> 16.1 | E38: =C38*$B$11 -> 215.74 | F38: =C38*$B$12 -> 106.26
A39: 21 | B39: =INT((A39-1)/12)+1 -> 2 | C39: =C38+25 -> 347 | D39: =C39*$B$10 -> 17.35 | E39: =C39*$B$11 -> 232.49 | F39: =C39*$B$12 -> 114.51
A40: 22 | B40: =INT((A40-1)/12)+1 -> 2 | C40: =C39+25 -> 372 | D40: =C40*$B$10 -> 18.6 | E40: =C40*$B$11 -> 249.24 | F40: =C40*$B$12 -> 122.76
A41: 23 | B41: =INT((A41-1)/12)+1 -> 2 | C41: =C40+25 -> 397 | D41: =C41*$B$10 -> 19.85 | E41: =C41*$B$11 -> 265.99 | F41: =C41*$B$12 -> 131.01
A42: 24 | B42: =INT((A42-1)/12)+1 -> 2 | C42: =C41+25 -> 422 | D42: =C42*$B$10 -> 21.1 | E42: =C42*$B$11 -> 282.74 | F42: =C42*$B$12 -> 139.26
A43: 25 | B43: =INT((A43-1)/12)+1 -> 3 | C43: =C42+110 -> 532 | D43: =C43*$B$10 -> 26.6 | E43: =C43*$B$11 -> 356.44 | F43: =C43*$B$12 -> 175.56
...

Sheet Revenue Model
A1: Revenue Model (36 Months)
A3: Pricing
A4: Pro (₱/mo) | B4: 299
A5: Business (₱/mo) | B5: 599
A6: Fee Rate | B6: 0.035
A7: Fee Fixed (₱) | B7: 15
A11: Month | B11: Pro | C11: Business | D11: Pro Rev | E11: Biz Rev | F11: Gross | G11: Fees | H11: Net
A12: 1 | B12: ='User Growth'!E19 -> 0.8 | C12: ='User Growth'!F19 -> 0 | D12: =B12*$B$4 -> 239.2 | E12: =C12*$B$5 -> 0 | F12: =D12+E12 -> 239.2 | G12: =IF(F12>0,F12*$B$6+$B$7,0) -> 23.372 | H12: =F12-G12 -> 215.828
A13: 2 | B13: ='User Growth'!E20 -> 1.44 | C13: ='User Growth'!F20 -> 0 | D13: =B13*$B$4 -> 430.56 | E13: =C13*$B$5 -> 0 | F13: =D13+E13 -> 430.56 | G13: =IF(F13>0,F13*$B$6+$B$7,0) -> 30.0696 | H13: =F13-G13 -> 400.4904
A14: 3 | B14: ='User Growth'!E21 -> 2.08 | C14: ='User Growth'!F21 -> 0 | D14: =B14*$B$4 -> 621.92 | E14: =C14*$B$5 -> 0 | F14: =D14+E14 -> 621.92 | G14: =IF(F14>0,F14*$B$6+$B$7,0) -> 36.7672 | H14: =F14-G14 -> 585.1528
A15: 4 | B15: ='User Growth'!E22 -> 2.72 | C15: ='User Growth'!F22 -> 0 | D15: =B15*$B$4 -> 813.28 | E15: =C15*$B$5 -> 0 | F15: =D15+E15 -> 813.28 | G15: =IF(F15>0,F15*$B$6+$B$7,0) -> 43.4648 | H15: =F15-G15 -> 769.8152
A16: 5 | B16: ='User Growth'!E23 -> 3.36 | C16: ='User Growth'!F23 -> 0 | D16: =B16*$B$4 -> 1004.64 | E16: =C16*$B$5 -> 0 | F16: =D16+E16 -> 1004.64 | G16: =IF(F16>0,F16*$B$6+$B$7,0) -> 50.1624 | H16: =F16-G16 -> 954.4776
A17: 6 | B17: ='User Growth'!E24 -> 4 | C17: ='User Growth'!F24 -> 0 | D17: =B17*$B$4 -> 1196 | E17: =C17*$B$5 -> 0 | F17: =D17+E17 -> 1196 | G17: =IF(F17>0,F17*$B$6+$B$7,0) -> 56.86 | H17: =F17-G17 -> 1139.14
A18: 7 | B18: ='User Growth'!E25 -> 4.96 | C18: ='User Growth'!F25 -> 0 | D18: =B18*$B$4 -> 1483.04 | E18: =C18*$B$5 -> 0 | F18: =D18+E18 -> 1483.04 | G18: =IF(F18>0,F18*$B$6+$B$7,0) -> 66.9064 | H18: =F18-G18 -> 1416.1336
A19: 8 | B19: ='User Growth'!E26 -> 5.92 | C19: ='User Growth'!F26 -> 0 | D19: =B19*$B$4 -> 1770.08 | E19: =C19*$B$5 -> 0 | F19: =D19+E19 -> 1770.08 | G19: =IF(F19>0,F19*$B$6+$B$7,0) -> 76.9528 | H19: =F19-G19 -> 1693.1272
A20: 9 | B20: ='User Growth'!E27 -> 6.88 | C20: ='User Growth'!F27 -> 0 | D20: =B20*$B$4 -> 2057.12 | E20: =C20*$B$5 -> 0 | F20: =D20+E20 -> 2057.12 | G20: =IF(F20>0,F20*$B$6+$B$7,0) -> 86.9992 | H20: =F20-G20 -> 1970.1208
A21: 10 | B21: ='User Growth'!E28 -> 7.84 | C21: ='User Growth'!F28 -> 0 | D21: =B21*$B$4 -> 2344.16 | E21: =C21*$B$5 -> 0 | F21: =D21+E21 -> 2344.16 | G21: =IF(F21>0,F21*$B$6+$B$7,0) -> 97.0456 | H21: =F21-G21 -> 2247.1144
A22: 11 | B22: ='User Growth'!E29 -> 8.8 | C22: ='User Growth'!F29 -> 0 | D22: =B22*$B$4 -> 2631.2 | E22: =C22*$B$5 -> 0 | F22: =D22+E22 -> 2631.2 | G22: =IF(F22>0,F22*$B$6+$B$7,0) -> 107.092 | H22: =F22-G22 -> 2524.108
A23: 12 | B23: ='User Growth'!E30 -> 9.76 | C23: ='User Growth'!F30 -> 0 | D23: =B23*$B$4 -> 2918.24 | E23: =C23*$B$5 -> 0 | F23: =D23+E23 -> 2918.24 | G23: =IF(F23>0,F23*$B$6+$B$7,0) -> 117.1384 | H23: =F23-G23 -> 2801.1016
... A47: 36 | B47: ='User Growth'!E54 -> 1167.14 | C47: ='User Growth'!F54 -> 574.86 | D47: =B47*$B$4 -> 348974.86 | E47: =C47*$B$5 -> 344341.14 | F47: =D47+E47 -> 693316 | G47: =IF(F47>0,F47*$B$6+$B$7,0) -> 24281.06 | H47: =F47-G47 -> 669034.94
A49: Annual Summary
A50: Year | B50: Revenue | C50: Fees | D50: Net
A51: 1 | B51: =SUM(F12:F23) -> 17509.44 | C51: =SUM(G12:G23) -> 792.8304 | D51: =SUM(H12:H23) -> 16716.61
A52: 2 | B52: =SUM(F24:F35) -> 1358772 | C52: =SUM(G24:G35) -> 47737.02 | D52: =SUM(H24:H35) -> 1311035
A53: 3 | B53: =SUM(F36:F47) -> 5430312 | C53: =SUM(G36:G47) -> 190240.92 | D53: =SUM(H36:H47) -> 5240071.1

Sheet CapEx
A1: CapEx - One-Time Costs
A3: Item | B3: Amount (₱)
A4: Legal & Compliance | B4: 35000
A5: BIR Registration | B5: 5000
A6: SEC/DTI Registration | B6: 3000
A7: Domain (3yr) | B7: 2500
A8: Accounting Setup | B8: 8000
A9: Bank Account | B9: 1000
A10: WhatsApp API | B10: 2000
A11: Contingency (10%) | B11: =SUM(B4:B10)*0.1 -> 5650
A12: TOTAL | B12: =SUM(B4:B11) -> 62150

Sheet OpEx Fixed
A1: OpEx - Fixed Monthly Costs
A3: Item | B3: USD/mo | C3: ₱/mo | D3: Y1 Annual | E3: Y2 Annual | F3: Y3 Annual
A4: Supabase Pro | B4: 25 | C4: =B4*57.2 -> 1430 | D4: =C4*12 -> 17160 | E4: =C4*12 -> 17160 | F4: =C4*12 -> 17160
A5: Vercel Pro | B5: 20 | C5: =B5*57.2 -> 1144 | D5: =C5*12 -> 13728 | E5: =C5*12 -> 13728 | F5: =C5*12 -> 13728
A6: Domain & SSL | B6: 1 | C6: =B6*57.2 -> 57.2 | D6: =C6*12 -> 686.4 | E6: =C6*12 -> 686.4 | F6: =C6*12 -> 686.4
A7: Sentry | B7: 26 | C7: =B7*57.2 -> 1487.2 | D7: =C7*12 -> 17846.4 | E7: =C7*12 -> 17846.4 | F7: =C7*12 -> 17846.4
A8: UptimeRobot | B8: 7 | C8: =B8*57.2 -> 400.4 | D8: =C8*12 -> 4804.8 | E8: =C8*12 -> 4804.8 | F8: =C8*12 -> 4804.8
A9: WhatsApp API | B9: 10 | C9: =B9*57.2 -> 572 | D9: =C9*12 -> 6864 | E9: =C9*12 -> 6864 | F9: =C9*12 -> 6864
A10: Google Workspace | B10: 6 | C10: =B10*57.2 -> 343.2 | D10: =C10*12 -> 4118.4 | E10: =C10*12 -> 4118.4 | F10: =C10*12 -> 4118.4
A11: PostHog | B11: 0 | C11: =B11*57.2 -> 0 | D11: 0 | E11: =42*57.2*12 -> 28828.8 | F11: =42*57.2*12 -> 28828.8
A12: Resend | B12: 0 | C12: =B12*57.2 -> 0 | D12: 0 | E12: =20*57.2*12 -> 13728 | F12: =20*57.2*12 -> 13728
A13: TOTAL | D13: =SUM(D4:D12) -> 65208 | E13: =SUM(E4:E12) -> 107764.8 | F13: =SUM(F4:F12) -> 107764.8

Sheet OpEx Variable
A1: OpEx Variable - Claude API Costs
A3: API Assumptions
A4: Exchange Rate | B4: 57.2
A5: Sonnet Input ($/M) | B5: 3
A6: Sonnet Output ($/M) | B6: 15
A7: Haiku Input ($/M) | B7: 0.8
A8: Haiku Output ($/M) | B8: 4
A9: Vision ($/1k req) | B9: 1.5
A10: Free: Sonnet In | B10: 40000
A11: Free: Sonnet Out | B11: 10000
A12: Free: Haiku In | B12: 15000
A13: Free: Haiku Out | B13: 6000
A14: Free: Vision | B14: 10
A15: Pro: Sonnet In | B15: 120000
... A24: Biz: Vision | B24: 50
A27: Month | B27: Free | C27: Pro | D27: Biz | E27: Free Cost | F27: Pro Cost | G27: Biz Cost | H27: Total Cost
A28: 1 | B28: ='User Growth'!D19 -> 1100 | C28: ='User Growth'!E19 -> 0.8 | D28: ='User Growth'!F19 -> 0 | E28: =B28*(($B$7*$B$2+$B$8*$B$3)/1000000+($B$9*$B$4+$B$10*$B$5)/1000000+$B$11*$B$6/1000)*$B$1 -> 0 | F28: =C28*(($B$12*$B$2+$B$13*$B$3)/1000000+($B$14*$B$4+$B$15*$B$5)/1000000+$B$16*$B$6/1000)*$B$1 -> 0 | G28: =D28*(($B$17*$B$2+$B$18*$B$3)/1000000+($B$19*$B$4+$B$20*$B$5)/1000000+$B$21*$B$6/1000)*$B$1 -> 0 | H28: =E28+F28+G28 -> 0
A29: 2 | B29: ='User Growth'!D20 -> 1980 | C29: ='User Growth'!E20 -> 1.44 | D29: ='User Growth'!F20 -> 0 | E29: =B29*(($B$7*$B$2+$B$8*$B$3)/1000000+($B$9*$B$4+$B$10*$B$5)/1000000+$B$11*$B$6/1000)*$B$1 -> 0 | F29: =C29*(($B$12*$B$2+$B$13*$B$3)/1000000+($B$14*$B$4+$B$15*$B$5)/1000000+$B$16*$B$6/1000)*$B$1 -> 0 | G29: =D29*(($B$17*$B$2+$B$18*$B$3)/1000000+($B$19*$B$4+$B$20*$B$5)/1000000+$B$21*$B$6/1000)*$B$1 -> 0 | H29: =E29+F29+G29 -> 0
A30: 3 | B30: ='User Growth'!D21 -> 2860 | C30: ='User Growth'!E21 -> 2.08 | D30: ='User Growth'!F21 -> 0 | E30: =B30*(($B$7*$B$2+$B$8*$B$3)/1000000+($B$9*$B$4+$B$10*$B$5)/1000000+$B$11*$B$6/1000)*$B$1 -> 0 | F30: =C30*(($B$12*$B$2+$B$13*$B$3)/1000000+($B$14*$B$4+$B$15*$B$5)/1000000+$B$16*$B$6/1000)*$B$1 -> 0 | G30: =D30*(($B$17*$B$2+$B$18*$B$3)/1000000+($B$19*$B$4+$B$20*$B$5)/1000000+$B$21*$B$6/1000)*$B$1 -> 0 | H30: =E30+F30+G30 -> 0
A31: 4 | B31: ='User Growth'!D22 -> 3740 | C31: ='User Growth'!E22 -> 2.72 | D31: ='User Growth'!F22 -> 0 | E31: =B31*(($B$7*$B$2+$B$8*$B$3)/1000000+($B$9*$B$4+$B$10*$B$5)/1000000+$B$11*$B$6/1000)*$B$1 -> 0 | F31: =C31*(($B$12*$B$2+$B$13*$B$3)/1000000+($B$14*$B$4+$B$15*$B$5)/1000000+$B$16*$B$6/1000)*$B$1 -> 0 | G31: =D31*(($B$17*$B$2+$B$18*$B$3)/1000000+($B$19*$B$4+$B$20*$B$5)/1000000+$B$21*$B$6/1000)*$B$1 -> 0 | H31: =E31+F31+G31 -> 0
A32: 5 | B32: ='User Growth'!D23 -> 4620 | C32: ='User Growth'!E23 -> 3.36 | D32: ='User Growth'!F23 -> 0 | E32: =B32*(($B$7*$B$2+$B$8*$B$3)/1000000+($B$9*$B$4+$B$10*$B$5)/1000000+$B$11*$B$6/1000)*$B$1 -> 0 | F32: =C32*(($B$12*$B$2+$B$13*$B$3)/1000000+($B$14*$B$4+$B$15*$B$5)/1000000+$B$16*$B$6/1000)*$B$1 -> 0 | G32: =D32*(($B$17*$B$2+$B$18*$B$3)/1000000+($B$19*$B$4+$B$20*$B$5)/1000000+$B$21*$B$6/1000)*$B$1 -> 0 | H32: =E32+F32+G32 -> 0
A33: 6 | B33: ='User Growth'!D24 -> 5500 | C33: ='User Growth'!E24 -> 4 | D33: ='User Growth'!F24 -> 0 | E33: =B33*(($B$7*$B$2+$B$8*$B$3)/1000000+($B$9*$B$4+$B$10*$B$5)/1000000+$B$11*$B$6/1000)*$B$1 -> 0 | F33: =C33*(($B$12*$B$2+$B$13*$B$3)/1000000+($B$14*$B$4+$B$15*$B$5)/1000000+$B$16*$B$6/1000)*$B$1 -> 0 | G33: =D33*(($B$17*$B$2+$B$18*$B$3)/1000000+($B$19*$B$4+$B$20*$B$5)/1000000+$B$21*$B$6/1000)*$B$1 -> 0 | H33: =E33+F33+G33 -> 0
A34: 7 | B34: ='User Growth'!D25 -> 6820 | C34: ='User Growth'!E25 -> 4.96 | D34: ='User Growth'!F25 -> 0 | E34: =B34*(($B$7*$B$2+$B$8*$B$3)/1000000+($B$9*$B$4+$B$10*$B$5)/1000000+$B$11*$B$6/1000)*$B$1 -> 0 | F34: =C34*(($B$12*$B$2+$B$13*$B$3)/1000000+($B$14*$B$4+$B$15*$B$5)/1000000+$B$16*$B$6/1000)*$B$1 -> 0 | G34: =D34*(($B$17*$B$2+$B$18*$B$3)/1000000+($B$19*$B$4+$B$20*$B$5)/1000000+$B$21*$B$6/1000)*$B$1 -> 0 | H34: =E34+F34+G34 -> 0
A35: 8 | B35: ='User Growth'!D26 -> 8140 | C35: ='User Growth'!E26 -> 5.92 | D35: ='User Growth'!F26 -> 0 | E35: =B35*(($B$7*$B$2+$B$8*$B$3)/1000000+($B$9*$B$4+$B$10*$B$5)/1000000+$B$11*$B$6/1000)*$B$1 -> 0 | F35: =C35*(($B$12*$B$2+$B$13*$B$3)/1000000+($B$14*$B$4+$B$15*$B$5)/1000000+$B$16*$B$6/1000)*$B$1 -> 0 | G35: =D35*(($B$17*$B$2+$B$18*$B$3)/1000000+($B$19*$B$4+$B$20*$B$5)/1000000+$B$21*$B$6/1000)*$B$1 -> 0 | H35: =E35+F35+G35 -> 0
A36: 9 | B36: ='User Growth'!D27 -> 9460 | C36: ='User Growth'!E27 -> 6.88 | D36: ='User Growth'!F27 -> 0 | E36: =B36*(($B$7*$B$2+$B$8*$B$3)/1000000+($B$9*$B$4+$B$10*$B$5)/1000000+$B$11*$B$6/1000)*$B$1 -> 0 | F36: =C36*(($B$12*$B$2+$B$13*$B$3)/1000000+($B$14*$B$4+$B$15*$B$5)/1000000+$B$16*$B$6/1000)*$B$1 -> 0 | G36: =D36*(($B$17*$B$2+$B$18*$B$3)/1000000+($B$19*$B$4+$B$20*$B$5)/1000000+$B$21*$B$6/1000)*$B$1 -> 0 | H36: =E36+F36+G36 -> 0
A37: 10 | B37: ='User Growth'!D28 -> 10780 | C37: ='User Growth'!E28 -> 7.84 | D37: ='User Growth'!F28 -> 0 | E37: =B37*(($B$7*$B$2+$B$8*$B$3)/1000000+($B$9*$B$4+$B$10*$B$5)/1000000+$B$11*$B$6/1000)*$B$1 -> 0 | F37: =C37*(($B$12*$B$2+$B$13*$B$3)/1000000+($B$14*$B$4+$B$15*$B$5)/1000000+$B$16*$B$6/1000)*$B$1 -> 0 | G37: =D37*(($B$17*$B$2+$B$18*$B$3)/1000000+($B$19*$B$4+$B$20*$B$5)/1000000+$B$21*$B$6/1000)*$B$1 -> 0 | H37: =E37+F37+G37 -> 0
A38: 11 | B38: ='User Growth'!D29 -> 12100 | C38: ='User Growth'!E29 -> 8.8 | D38: ='User Growth'!F29 -> 0 | E38: =B38*(($B$7*$B$2+$B$8*$B$3)/1000000+($B$9*$B$4+$B$10*$B$5)/1000000+$B$11*$B$6/1000)*$B$1 -> 0 | F38: =C38*(($B$12*$B$2+$B$13*$B$3)/1000000+($B$14*$B$4+$B$15*$B$5)/1000000+$B$16*$B$6/1000)*$B$1 -> 0 | G38: =D38*(($B$17*$B$2+$B$18*$B$3)/1000000+($B$19*$B$4+$B$20*$B$5)/1000000+$B$21*$B$6/1000)*$B$1 -> 0 | H38: =E38+F38+G38 -> 0
A39: 12 | B39: ='User Growth'!D30 -> 13420 | C39: ='User Growth'!E30 -> 9.76 | D39: ='User Growth'!F30 -> 0 | E39: =B39*(($B$7*$B$2+$B$8*$B$3)/1000000+($B$9*$B$4+$B$10*$B$5)/1000000+$B$11*$B$6/1000)*$B$1 -> 0 | F39: =C39*(($B$12*$B$2+$B$13*$B$3)/1000000+($B$14*$B$4+$B$15*$B$5)/1000000+$B$16*$B$6/1000)*$B$1 -> 0 | G39: =D39*(($B$17*$B$2+$B$18*$B$3)/1000000+($B$19*$B$4+$B$20*$B$5)/1000000+$B$21*$B$6/1000)*$B$1 -> 0 | H39: =E39+F39+G39 -> 0
... A63: 36 | B63: ='User Growth'!D54 -> 87.1 | C63: ='User Growth'!E54 -> 1167.14 | D63: ='User Growth'!F54 -> 574.86 | E63: =B63*(($B$7*$B$2+$B$8*$B$3)/1000000+($B$9*$B$4+$B$10*$B$5)/1000000+$B$11*$B$6/1000)*$B$1 -> 0 | F63: =C63*(($B$12*$B$2+$B$13*$B$3)/1000000+($B$14*$B$4+$B$15*$B$5)/1000000+$B$16*$B$6/1000)*$B$1 -> 0 | G63: =D63*(($B$17*$B$2+$B$18*$B$3)/1000000+($B$19*$B$4+$B$20*$B$5)/1000000+$B$21*$B$6/1000)*$B$1 -> 0 | H63: =E63+F63+G63 -> 0
A65: Annual Summary
A66: Year | B66: Total API Cost
A67: 1 | B67: =SUM(H28:H39) -> 0
A68: 2 | B68: =SUM(H40:H51) -> 0
A69: 3 | B69: =SUM(H52:H63) -> 0

Sheet P&L Summary
A1: P&L Summary - 3 Year Projection
B3: Year 1 | C3: Year 2 | D3: Year 3
A4: REVENUE
A5: Gross Revenue | B5: ='Revenue Model'!B51 -> 17509.44 | C5: ='Revenue Model'!B52 -> 1358772 | D5: ='Revenue Model'!B53 -> 5430312
A6: Less: PayMongo Fees | B6: =-'Revenue Model'!C51 -> -792.8304 | C6: =-'Revenue Model'!C52 -> -47737.02 | D6: =-'Revenue Model'!C53 -> -190240.92
A7: NET REVENUE | B7: =B5-B6 -> 18302.27 | C7: =C5-C6 -> 1406509 | D7: =D5-D6 -> 5620552.9
A9: COSTS
A10: Claude API Costs | B10: ='OpEx Variable'!B67 -> 0 | C10: ='OpEx Variable'!B68 -> 0 | D10: ='OpEx Variable'!B69 -> 0
A11: Fixed OpEx | B11: ='OpEx Fixed'!D4 -> 17160 | C11: ='OpEx Fixed'!E4 -> 17160 | D11: ='OpEx Fixed'!F4 -> 17160
A12: TOTAL COSTS | B12: =B9+B10 -> 0 | C12: =C9+C10 -> 0 | D12: =D9+D10 -> 0
A14: GROSS PROFIT | B14: =B7-B11 -> 1142.2704 | C14: =C7-C11 -> 1389349 | D14: =D7-D11 -> 5603392.9
A15: GROSS MARGIN % | B15: =IF(B7>0,B12/B7,0) -> 0 | C15: =IF(C7>0,C12/C7,0) -> 0 | D15: =IF(D7>0,D12/D7,0) -> 0
A17: ONE-TIME COSTS
A18: CapEx | B18: =CapEx!B12 -> 62150
A19: NET PROFIT/(LOSS) | B19: =B12-B17 -> 0 | C19: =C12 -> 0 | D19: =D12 -> 0

Sheet Break-Even Analysis
A1: Break-Even Analysis (36 Months)
A3: Month | B3: Cum Revenue | C3: Cum Costs | D3: Cum Net | E3: Break-Even?
A4: 1 | B4: ='Revenue Model'!H12 -> 215.828 | C4: =CapEx!B12+('OpEx Fixed'!D4)+('OpEx Variable'!H28) -> 79310 | D4: =B4-C4 -> -79094.172 | E4: =IF(D4>=0,"YES","NO") -> NO
A5: 2 | B5: =B4+'Revenue Model'!H13 -> 616.3184 | C5: =C4+('OpEx Fixed'!D4)+('OpEx Variable'!H29) -> 96470 | D5: =B5-C5 -> -95853.682 | E5: =IF(D5>=0,"YES","NO") -> NO
A6: 3 | B6: =B5+'Revenue Model'!H14 -> 1201.4712 | C6: =C5+('OpEx Fixed'!D4)+('OpEx Variable'!H30) -> 113630 | D6: =B6-C6 -> -112428.53 | E6: =IF(D6>=0,"YES","NO") -> NO
A7: 4 | B7: =B6+'Revenue Model'!H15 -> 1971.2864 | C7: =C6+('OpEx Fixed'!D4)+('OpEx Variable'!H31) -> 130790 | D7: =B7-C7 -> -128818.71 | E7: =IF(D7>=0,"YES","NO") -> NO
A8: 5 | B8: =B7+'Revenue Model'!H16 -> 2925.764 | C8: =C7+('OpEx Fixed'!D4)+('OpEx Variable'!H32) -> 147950 | D8: =B8-C8 -> -145024.24 | E8: =IF(D8>=0,"YES","NO") -> NO
A9: 6 | B9: =B8+'Revenue Model'!H17 -> 4064.904 | C9: =C8+('OpEx Fixed'!D4)+('OpEx Variable'!H33) -> 165110 | D9: =B9-C9 -> -161045.1 | E9: =IF(D9>=0,"YES","NO") -> NO
A10: 7 | B10: =B9+'Revenue Model'!H18 -> 5481.0376 | C10: =C9+('OpEx Fixed'!D4)+('OpEx Variable'!H34) -> 182270 | D10: =B10-C10 -> -176788.96 | E10: =IF(D10>=0,"YES","NO") -> NO
A11: 8 | B11: =B10+'Revenue Model'!H19 -> 7174.1648 | C11: =C10+('OpEx Fixed'!D4)+('OpEx Variable'!H35) -> 199430 | D11: =B11-C11 -> -192255.84 | E11: =IF(D11>=0,"YES","NO") -> NO
A12: 9 | B12: =B11+'Revenue Model'!H20 -> 9144.2856 | C12: =C11+('OpEx Fixed'!D4)+('OpEx Variable'!H36) -> 216590 | D12: =B12-C12 -> -207445.71 | E12: =IF(D12>=0,"YES","NO") -> NO
A13: 10 | B13: =B12+'Revenue Model'!H21 -> 11391.4 | C13: =C12+('OpEx Fixed'!D4)+('OpEx Variable'!H37) -> 233750 | D13: =B13-C13 -> -222358.6 | E13: =IF(D13>=0,"YES","NO") -> NO
A14: 11 | B14: =B13+'Revenue Model'!H22 -> 13915.508 | C14: =C13+('OpEx Fixed'!D4)+('OpEx Variable'!H38) -> 250910 | D14: =B14-C14 -> -236994.49 | E14: =IF(D14>=0,"YES","NO") -> NO
A15: 12 | B15: =B14+'Revenue Model'!H23 -> 16716.61 | C15: =C14+('OpEx Fixed'!D4)+('OpEx Variable'!H39) -> 268070 | D15: =B15-C15 -> -251353.39 | E15: =IF(D15>=0,"YES","NO") -> NO
A16: 13 | B16: =B15+'Revenue Model'!H24 -> 73159.9 | C16: =C15+('OpEx Fixed'!D4)+('OpEx Variable'!H40) -> 285230 | D16: =B16-C16 -> -212070.1 | E16: =IF(D16>=0,"YES","NO") -> NO
A17: 14 | B17: =B16+'Revenue Model'!H25 -> 139204.94 | C17: =C16+('OpEx Fixed'!D4)+('OpEx Variable'!H41) -> 302390 | D17: =B17-C17 -> -163185.06 | E17: =IF(D17>=0,"YES","NO") -> NO
A18: 15 | B18: =B17+'Revenue Model'!H26 -> 214851.73 | C18: =C17+('OpEx Fixed'!D4)+('OpEx Variable'!H42) -> 319550 | D18: =B18-C18 -> -104698.27 | E18: =IF(D18>=0,"YES","NO") -> NO
A19: 16 | B19: =B18+'Revenue Model'!H27 -> 300100.27 | C19: =C18+('OpEx Fixed'!D4)+('OpEx Variable'!H43) -> 336710 | D19: =B19-C19 -> -36609.73 | E19: =IF(D19>=0,"YES","NO") -> NO
A20: 17 | B20: =B19+'Revenue Model'!H28 -> 394950.56 | C20: =C19+('OpEx Fixed'!D4)+('OpEx Variable'!H44) -> 353870 | D20: =B20-C20 -> 41080.56 | E20: =IF(D20>=0,"YES","NO") -> YES
A21: 18 | B21: =B20+'Revenue Model'!H29 -> 499402.6 | C21: =C20+('OpEx Fixed'!D4)+('OpEx Variable'!H45) -> 371030 | D21: =B21-C21 -> 128372.6 | E21: =IF(D21>=0,"YES","NO") -> YES
A22: 19 | B22: =B21+'Revenue Model'!H30 -> 613456.39 | C22: =C21+('OpEx Fixed'!D4)+('OpEx Variable'!H46) -> 388190 | D22: =B22-C22 -> 225266.39 | E22: =IF(D22>=0,"YES","NO") -> YES
A23: 20 | B23: =B22+'Revenue Model'!H31 -> 737111.93 | C23: =C22+('OpEx Fixed'!D4)+('OpEx Variable'!H47) -> 405350 | D23: =B23-C23 -> 331761.93 | E23: =IF(D23>=0,"YES","NO") -> YES
A24: 21 | B24: =B23+'Revenue Model'!H32 -> 870369.22 | C24: =C23+('OpEx Fixed'!D4)+('OpEx Variable'!H48) -> 422510 | D24: =B24-C24 -> 447859.22 | E24: =IF(D24>=0,"YES","NO") -> YES
A25: 22 | B25: =B24+'Revenue Model'!H33 -> 1013228.3 | C25: =C24+('OpEx Fixed'!D4)+('OpEx Variable'!H49) -> 439670 | D25: =B25-C25 -> 573558.26 | E25: =IF(D25>=0,"YES","NO") -> YES
A26: 23 | B26: =B25+'Revenue Model'!H34 -> 1165689 | C26: =C25+('OpEx Fixed'!D4)+('OpEx Variable'!H50) -> 456830 | D26: =B26-C26 -> 708859.05 | E26: =IF(D26>=0,"YES","NO") -> YES
A27: 24 | B27: =B26+'Revenue Model'!H35 -> 1327751.6 | C27: =C26+('OpEx Fixed'!D4)+('OpEx Variable'!H51) -> 473990 | D27: =B27-C27 -> 853761.59 | E27: =IF(D27>=0,"YES","NO") -> YES
A28: 25 | B28: =B27+'Revenue Model'!H36 -> 1532061.8 | C28: =C27+('OpEx Fixed'!D4)+('OpEx Variable'!H52) -> 491150 | D28: =B28-C28 -> 1040911.8 | E28: =IF(D28>=0,"YES","NO") -> YES
A29: 26 | B29: =B28+'Revenue Model'!H37 -> 1778619.8 | C29: =C28+('OpEx Fixed'!D4)+('OpEx Variable'!H53) -> 508310 | D29: =B29-C29 -> 1270309.8 | E29: =IF(D29>=0,"YES","NO") -> YES
A30: 27 | B30: =B29+'Revenue Model'!H38 -> 2067425.4 | C30: =C29+('OpEx Fixed'!D4)+('OpEx Variable'!H54) -> 525470 | D30: =B30-C30 -> 1541955.4 | E30: =IF(D30>=0,"YES","NO") -> YES
A31: 28 | B31: =B30+'Revenue Model'!H39 -> 2398478.7 | C31: =C30+('OpEx Fixed'!D4)+('OpEx Variable'!H55) -> 542630 | D31: =B31-C31 -> 1855848.7 | E31: =IF(D31>=0,"YES","NO") -> YES
A32: 29 | B32: =B31+'Revenue Model'!H40 -> 2771779.8 | C32: =C31+('OpEx Fixed'!D4)+('OpEx Variable'!H56) -> 559790 | D32: =B32-C32 -> 2211989.8 | E32: =IF(D32>=0,"YES","NO") -> YES
A33: 30 | B33: =B32+'Revenue Model'!H41 -> 3187328.5 | C33: =C32+('OpEx Fixed'!D4)+('OpEx Variable'!H57) -> 576950 | D33: =B33-C33 -> 2610378.5 | E33: =IF(D33>=0,"YES","NO") -> YES
A34: 31 | B34: =B33+'Revenue Model'!H42 -> 3645125 | C34: =C33+('OpEx Fixed'!D4)+('OpEx Variable'!H58) -> 594110 | D34: =B34-C34 -> 3051015 | E34: =IF(D34>=0,"YES","NO") -> YES
A35: 32 | B35: =B34+'Revenue Model'!H43 -> 4145169.1 | C35: =C34+('OpEx Fixed'!D4)+('OpEx Variable'!H59) -> 611270 | D35: =B35-C35 -> 3533899.1 | E35: =IF(D35>=0,"YES","NO") -> YES
A36: 33 | B36: =B35+'Revenue Model'!H44 -> 4687460.9 | C36: =C35+('OpEx Fixed'!D4)+('OpEx Variable'!H60) -> 628430 | D36: =B36-C36 -> 4059030.9 | E36: =IF(D36>=0,"YES","NO") -> YES
A37: 34 | B37: =B36+'Revenue Model'!H45 -> 5272000.5 | C37: =C36+('OpEx Fixed'!D4)+('OpEx Variable'!H61) -> 645590 | D37: =B37-C37 -> 4626410.5 | E37: =IF(D37>=0,"YES","NO") -> YES
A38: 35 | B38: =B37+'Revenue Model'!H46 -> 5898787.7 | C38: =C37+('OpEx Fixed'!D4)+('OpEx Variable'!H62) -> 662750 | D38: =B38-C38 -> 5236037.7 | E38: =IF(D38>=0,"YES","NO") -> YES
A39: 36 | B39: =B38+'Revenue Model'!H47 -> 6567822.7 | C39: =C38+('OpEx Fixed'!D4)+('OpEx Variable'!H63) -> 679910 | D39: =B39-C39 -> 5887912.7 | E39: =IF(D39>=0,"YES","NO") -> YES

Sheet Scenario Comparison
A1: Scenario Comparison - Year 3
A3: Metric | B3: Conservative (800) | C3: Moderate (2,000) BASE | D3: Aggressive (5,000)
A4: Total Users Y3 | B4: 800 | C4: 2000 | D4: 5000
A5: Paying Users (38%) | B5: 304 | C5: 760 | D5: 1900
A6: MRR Y3 (₱) | B6: =304*((299*0.33+599*0.05)) -> 39100.48 | C6: ='Revenue Model'!D53 -> 5240071.1 | D6: =1900*((299*0.33+599*0.05)) -> 244378
A7: ARR Y3 (₱) | B7: =G6*12 -> 0 | C7: =H6*12 -> 0 | D7: =I6*12 -> 0
A8: Net Profit Y3 (₱)

Sheet Assumptions
A1: All Model Assumptions
A3: Category | B3: Assumption | C3: Value
A4: EXCHANGE | B4: ₱ per $1 USD | C4: 57.20
A5: PRICING | B5: Pro Price (₱/mo) | C5: 299
A6: PRICING | B6: Business Price (₱/mo) | C6: 599
A7: PRICING | B7: PayMongo Fee | C7: 3.5% + ₱15
A8: USER GROWTH | B8: Month 1 Launch | C8: 10 users
A9: USER GROWTH | B9: Months 1-6 | C9: +8/month
A10: USER GROWTH | B10: Months 7-12 | C10: +12/month
A11: USER GROWTH | B11: Year 2 | C11: +25/month
A12: USER GROWTH | B12: Year 3 | C12: +110/month
A13: CHURN | B13: Free Users | C13: 8%
A14: CHURN | B14: Paid Users | C14: 5%
... A24: API PRICING | B24: Vision: $ per 1k req | C24: $1.50
